Workbook

Sheet origen_datos_mensuales
A1: Cliente | B1: Estado Cliente | C1: Mes Registro | D1: Mes de Abandono (Churn) | E1: 1/2019 | F1: 2/2019 | G1: 3/2019 | H1: 4/2019 | I1: 5/2019 | J1: 6/2019 | K1: 7/2019 | L1: 8/2019 | M1: 9/2019 | N1: 10/2019 | O1: 11/2019 | P1: 12/2019 | Q1: 1/2020 | R1: 2/2020 | S1: 3/2020 | T1: 4/2020 | U1: 5/2020 | V1: 6/2020 | W1: 7/2020 | X1: 8/2020 | Y1: 9/2020 | Z1: 10/2020 | AA1: 11/2020 | AB1: 12/2020
A2: George Garcia | B2: Active | C2: 43466 | E2: 1 | F2: 1 | G2: 1 | H2: 1 | I2: 1 | J2: 1 | K2: 1 | L2: 1 | M2: 1 | N2: 1 | O2: 1 | P2: 1 | Q2: 1 | R2: 1 | S2: 1 | T2: 1 | U2: 1 | V2: 1 | W2: 1 | X2: 1 | Y2: 1 | Z2: 1 | AA2: 1 | AB2: 1
A3: James Johnson | B3: Churned | C3: 43466 | D3: 43525 | E3: 1 | F3: 1 | G3: 0 | H3: 0 | I3: 0 | J3: 0 | K3: 0 | L3: 0 | M3: 0 | N3: 0 | O3: 0 | P3: 0 | Q3: 0 | R3: 0 | S3: 0 | T3: 0 | U3: 0 | V3: 0 | W3: 0 | X3: 0 | Y3: 0 | Z3: 0 | AA3: 0 | AB3: 0
A4: John Williams | B4: Churned | C4: 43466 | D4: 43678 | E4: 1 | F4: 1 | G4: 1 | H4: 1 | I4: 1 | J4: 1 | K4: 1 | L4: 0 | M4: 0 | N4: 0 | O4: 0 | P4: 0 | Q4: 0 | R4: 0 | S4: 0 | T4: 0 | U4: 0 | V4: 0 | W4: 0 | X4: 0 | Y4: 0 | Z4: 0 | AA4: 0 | AB4: 0
A5: Robert Jones | B5: Active | C5: 43466 | E5: 1 | F5: 1 | G5: 1 | H5: 1 | I5: 1 | J5: 1 | K5: 1 | L5: 1 | M5: 1 | N5: 1 | O5: 1 | P5: 1 | Q5: 1 | R5: 1 | S5: 1 | T5: 1 | U5: 1 | V5: 1 | W5: 1 | X5: 1 | Y5: 1 | Z5: 1 | AA5: 1 | AB5: 1
A6: Michael Brown | B6: Active | C6: 43466 | E6: 1 | F6: 1 | G6: 1 | H6: 1 | I6: 1 | J6: 1 | K6: 1 | L6: 1 | M6: 1 | N6: 1 | O6: 1 | P6: 1 | Q6: 1 | R6: 1 | S6: 1 | T6: 1 | U6: 1 | V6: 1 | W6: 1 | X6: 1 | Y6: 1 | Z6: 1 | AA6: 1 | AB6: 1
A7: Mary Davis | B7: Churned | C7: 43466 | D7: 44075 | E7: 1 | F7: 1 | G7: 1 | H7: 1 | I7: 1 | J7: 1 | K7: 1 | L7: 1 | M7: 1 | N7: 1 | O7: 1 | P7: 1 | Q7: 1 | R7: 1 | S7: 1 | T7: 1 | U7: 1 | V7: 1 | W7: 1 | X7: 1 | Y7: 0 | Z7: 0 | AA7: 0 | AB7: 0
A8: William Miller | B8: Active | C8: 43466 | E8: 1 | F8: 1 | G8: 1 | H8: 1 | I8: 1 | J8: 1 | K8: 1 | L8: 1 | M8: 1 | N8: 1 | O8: 1 | P8: 1 | Q8: 1 | R8: 1 | S8: 1 | T8: 1 | U8: 1 | V8: 1 | W8: 1 | X8: 1 | Y8: 1 | Z8: 1 | AA8: 1 | AB8: 1
A9: David Wilson | B9: Active | C9: 43466 | E9: 1 | F9: 1 | G9: 1 | H9: 1 | I9: 1 | J9: 1 | K9: 1 | L9: 1 | M9: 1 | N9: 1 | O9: 1 | P9: 1 | Q9: 1 | R9: 1 | S9: 1 | T9: 1 | U9: 1 | V9: 1 | W9: 1 | X9: 1 | Y9: 1 | Z9: 1 | AA9: 1 | AB9: 1
A10: Joseph Moore | B10: Churned | C10: 43466 | D10: 43709 | E10: 1 | F10: 1 | G10: 1 | H10: 1 | I10: 1 | J10: 1 | K10: 1 | L10: 1 | M10: 0 | N10: 0 | O10: 0 | P10: 0 | Q10: 0 | R10: 0 | S10: 0 | T10: 0 | U10: 0 | V10: 0 | W10: 0 | X10: 0 | Y10: 0 | Z10: 0 | AA10: 0 | AB10: 0
A11: Richard Taylor | B11: Active | C11: 43466 | E11: 1 | F11: 1 | G11: 1 | H11: 1 | I11: 1 | J11: 1 | K11: 1 | L11: 1 | M11: 1 | N11: 1 | O11: 1 | P11: 1 | Q11: 1 | R11: 1 | S11: 1 | T11: 1 | U11: 1 | V11: 1 | W11: 1 | X11: 1 | Y11: 1 | Z11: 1 | AA11: 1 | AB11: 1
A12: Charles Anderson | B12: Active | C12: 43466 | E12: 1 | F12: 1 | G12: 1 | H12: 1 | I12: 1 | J12: 1 | K12: 1 | L12: 1 | M12: 1 | N12: 1 | O12: 1 | P12: 1 | Q12: 1 | R12: 1 | S12: 1 | T12: 1 | U12: 1 | V12: 1 | W12: 1 | X12: 1 | Y12: 1 | Z12: 1 | AA12: 1 | AB12: 1
A13: Thomas Thomas | B13: Churned | C13: 43497 | D13: 43739 | E13: 0 | F13: 1 | G13: 1 | H13: 1 | I13: 1 | J13: 1 | K13: 1 | L13: 1 | M13: 1 | N13: 0 | O13: 0 | P13: 0 | Q13: 0 | R13: 0 | S13: 0 | T13: 0 | U13: 0 | V13: 0 | W13: 0 | X13: 0 | Y13: 0 | Z13: 0 | AA13: 0 | AB13: 0
A14: Christopher Jackson | B14: Churned | C14: 43497 | D14: 43556 | E14: 0 | F14: 1 | G14: 1 | H14: 0 | I14: 0 | J14: 0 | K14: 0 | L14: 0 | M14: 0 | N14: 0 | O14: 0 | P14: 0 | Q14: 0 | R14: 0 | S14: 0 | T14: 0 | U14: 0 | V14: 0 | W14: 0 | X14: 0 | Y14: 0 | Z14: 0 | AA14: 0 | AB14: 0
A15: Daniel White | B15: Churned | C15: 43497 | D15: 43617 | E15: 0 | F15: 1 | G15: 1 | H15: 1 | I15: 1 | J15: 0 | K15: 0 | L15: 0 | M15: 0 | N15: 0 | O15: 0 | P15: 0 | Q15: 0 | R15: 0 | S15: 0 | T15: 0 | U15: 0 | V15: 0 | W15: 0 | X15: 0 | Y15: 0 | Z15: 0 | AA15: 0 | AB15: 0
A16: Elizabeth Harris | B16: Active | C16: 43497 | E16: 0 | F16: 1 | G16: 1 | H16: 1 | I16: 1 | J16: 1 | K16: 1 | L16: 1 | M16: 1 | N16: 1 | O16: 1 | P16: 1 | Q16: 1 | R16: 1 | S16: 1 | T16: 1 | U16: 1 | V16: 1 | W16: 1 | X16: 1 | Y16: 1 | Z16: 1 | AA16: 1 | AB16: 1
A17: Matthew Martin | B17: Active | C17: 43497 | E17: 0 | F17: 1 | G17: 1 | H17: 1 | I17: 1 | J17: 1 | K17: 1 | L17: 1 | M17: 1 | N17: 1 | O17: 1 | P17: 1 | Q17: 1 | R17: 1 | S17: 1 | T17: 1 | U17: 1 | V17: 1 | W17: 1 | X17: 1 | Y17: 1 | Z17: 1 | AA17: 1 | AB17: 1
A18: Patricia Thompson | B18: Active | C18: 43497 | E18: 0 | F18: 1 | G18: 1 | H18: 1 | I18: 1 | J18: 1 | K18: 1 | L18: 1 | M18: 1 | N18: 1 | O18: 1 | P18: 1 | Q18: 1 | R18: 1 | S18: 1 | T18: 1 | U18: 1 | V18: 1 | W18: 1 | X18: 1 | Y18: 1 | Z18: 1 | AA18: 1 | AB18: 1
A19: Brian Smith | B19: Churned | C19: 43497 | D19: 43770 | E19: 0 | F19: 1 | G19: 1 | H19: 1 | I19: 1 | J19: 1 | K19: 1 | L19: 1 | M19: 1 | N19: 1 | O19: 0 | P19: 0 | Q19: 0 | R19: 0 | S19: 0 | T19: 0 | U19: 0 | V19: 0 | W19: 0 | X19: 0 | Y19: 0 | Z19: 0 | AA19: 0 | AB19: 0
A20: Jennifer Martinez | B20: Active | C20: 43497 | E20: 0 | F20: 1 | G20: 1 | H20: 1 | I20: 1 | J20: 1 | K20: 1 | L20: 1 | M20: 1 | N20: 1 | O20: 1 | P20: 1 | Q20: 1 | R20: 1 | S20: 1 | T20: 1 | U20: 1 | V20: 1 | W20: 1 | X20: 1 | Y20: 1 | Z20: 1 | AA20: 1 | AB20: 1
A21: Linda Robinson | B21: Churned | C21: 43497 | D21: 43586 | E21: 0 | F21: 1 | G21: 1 | H21: 1 | I21: 0 | J21: 0 | K21: 0 | L21: 0 | M21: 0 | N21: 0 | O21: 0 | P21: 0 | Q21: 0 | R21: 0 | S21: 0 | T21: 0 | U21: 0 | V21: 0 | W21: 0 | X21: 0 | Y21: 0 | Z21: 0 | AA21: 0 | AB21: 0
A22: Anthony Clark | B22: Active | C22: 43497 | E22: 0 | F22: 1 | G22: 1 | H22: 1 | I22: 1 | J22: 1 | K22: 1 | L22: 1 | M22: 1 | N22: 1 | O22: 1 | P22: 1 | Q22: 1 | R22: 1 | S22: 1 | T22: 1 | U22: 1 | V22: 1 | W22: 1 | X22: 1 | Y22: 1 | Z22: 1 | AA22: 1 | AB22: 1
A23: Barbara Rodriguez | B23: Active | C23: 43497 | E23: 0 | F23: 1 | G23: 1 | H23: 1 | I23: 1 | J23: 1 | K23: 1 | L23: 1 | M23: 1 | N23: 1 | O23: 1 | P23: 1 | Q23: 1 | R23: 1 | S23: 1 | T23: 1 | U23: 1 | V23: 1 | W23: 1 | X23: 1 | Y23: 1 | Z23: 1 | AA23: 1 | AB23: 1
A24: Donald Lewis | B24: Active | C24: 43497 | E24: 0 | F24: 1 | G24: 1 | H24: 1 | I24: 1 | J24: 1 | K24: 1 | L24: 1 | M24: 1 | N24: 1 | O24: 1 | P24: 1 | Q24: 1 | R24: 1 | S24: 1 | T24: 1 | U24: 1 | V24: 1 | W24: 1 | X24: 1 | Y24: 1 | Z24: 1 | AA24: 1 | AB24: 1
A25: Paul Lee | B25: Active | C25: 43497 | E25: 0 | F25: 1 | G25: 1 | H25: 1 | I25: 1 | J25: 1 | K25: 1 | L25: 1 | M25: 1 | N25: 1 | O25: 1 | P25: 1 | Q25: 1 | R25: 1 | S25: 1 | T25: 1 | U25: 1 | V25: 1 | W25: 1 | X25: 1 | Y25: 1 | Z25: 1 | AA25: 1 | AB25: 1
A26: Mark Walker | B26: Churned | C26: 43525 | D26: 43891 | E26: 0 | F26: 0 | G26: 1 | H26: 1 | I26: 1 | J26: 1 | K26: 1 | L26: 1 | M26: 1 | N26: 1 | O26: 1 | P26: 1 | Q26: 1 | R26: 1 | S26: 0 | T26: 0 | U26: 0 | V26: 0 | W26: 0 | X26: 0 | Y26: 0 | Z26: 0 | AA26: 0 | AB26: 0
A27: Andrew Hall | B27: Active | C27: 43525 | E27: 0 | F27: 0 | G27: 1 | H27: 1 | I27: 1 | J27: 1 | K27: 1 | L27: 1 | M27: 1 | N27: 1 | O27: 1 | P27: 1 | Q27: 1 | R27: 1 | S27: 1 | T27: 1 | U27: 1 | V27: 1 | W27: 1 | X27: 1 | Y27: 1 | Z27: 1 | AA27: 1 | AB27: 1
A28: Edward Allen | B28: Churned | C28: 43525 | D28: 43739 | E28: 0 | F28: 0 | G28: 1 | H28: 1 | I28: 1 | J28: 1 | K28: 1 | L28: 1 | M28: 1 | N28: 0 | O28: 0 | P28: 0 | Q28: 0 | R28: 0 | S28: 0 | T28: 0 | U28: 0 | V28: 0 | W28: 0 | X28: 0 | Y28: 0 | Z28: 0 | AA28: 0 | AB28: 0
A29: Steven Young | B29: Churned | C29: 43525 | D29: 44105 | E29: 0 | F29: 0 | G29: 1 | H29: 1 | I29: 1 | J29: 1 | K29: 1 | L29: 1 | M29: 1 | N29: 1 | O29: 1 | P29: 1 | Q29: 1 | R29: 1 | S29: 1 | T29: 1 | U29: 1 | V29: 1 | W29: 1 | X29: 1 | Y29: 1 | Z29: 0 | AA29: 0 | AB29: 0
A30: Kenneth Hernandez | B30: Churned | C30: 43525 | D30: 44075 | E30: 0 | F30: 0 | G30: 1 | H30: 1 | I30: 1 | J30: 1 | K30: 1 | L30: 1 | M30: 1 | N30: 1 | O30: 1 | P30: 1 | Q30: 1 | R30: 1 | S30: 1 | T30: 1 | U30: 1 | V30: 1 | W30: 1 | X30: 1 | Y30: 0 | Z30: 0 | AA30: 0 | AB30: 0
A31: Margaret King | B31: Churned | C31: 43525 | D31: 43983 | E31: 0 | F31: 0 | G31: 1 | H31: 1 | I31: 1 | J31: 1 | K31: 1 | L31: 1 | M31: 1 | N31: 1 | O31: 1 | P31: 1 | Q31: 1 | R31: 1 | S31: 1 | T31: 1 | U31: 1 | V31: 0 | W31: 0 | X31: 0 | Y31: 0 | Z31: 0 | AA31: 0 | AB31: 0
A32: Joshua Wright | B32: Churned | C32: 43525 | D32: 43709 | E32: 0 | F32: 0 | G32: 1 | H32: 1 | I32: 1 | J32: 1 | K32: 1 | L32: 1 | M32: 0 | N32: 0 | O32: 0 | P32: 0 | Q32: 0 | R32: 0 | S32: 0 | T32: 0 | U32: 0 | V32: 0 | W32: 0 | X32: 0 | Y32: 0 | Z32: 0 | AA32: 0 | AB32: 0
A33: Kevin Lopez | B33: Churned | C33: 43525 | D33: 43952 | E33: 0 | F33: 0 | G33: 1 | H33: 1 | I33: 1 | J33: 1 | K33: 1 | L33: 1 | M33: 1 | N33: 1 | O33: 1 | P33: 1 | Q33: 1 | R33: 1 | S33: 1 | T33: 1 | U33: 0 | V33: 0 | W33: 0 | X33: 0 | Y33: 0 | Z33: 0 | AA33: 0 | AB33: 0
A34: Brian Hill | B34: Active | C34: 43525 | E34: 0 | F34: 0 | G34: 1 | H34: 1 | I34: 1 | J34: 1 | K34: 1 | L34: 1 | M34: 1 | N34: 1 | O34: 1 | P34: 1 | Q34: 1 | R34: 1 | S34: 1 | T34: 1 | U34: 1 | V34: 1 | W34: 1 | X34: 1 | Y34: 1 | Z34: 1 | AA34: 1 | AB34: 1
A35: Susan Scott | B35: Active | C35: 43525 | E35: 0 | F35: 0 | G35: 1 | H35: 1 | I35: 1 | J35: 1 | K35: 1 | L35: 1 | M35: 1 | N35: 1 | O35: 1 | P35: 1 | Q35: 1 | R35: 1 | S35: 1 | T35: 1 | U35: 1 | V35: 1 | W35: 1 | X35: 1 | Y35: 1 | Z35: 1 | AA35: 1 | AB35: 1
A36: Dorothy Green | B36: Churned | C36: 43525 | D36: 43952 | E36: 0 | F36: 0 | G36: 1 | H36: 1 | I36: 1 | J36: 1 | K36: 1 | L36: 1 | M36: 1 | N36: 1 | O36: 1 | P36: 1 | Q36: 1 | R36: 1 | S36: 1 | T36: 1 | U36: 0 | V36: 0 | W36: 0 | X36: 0 | Y36: 0 | Z36: 0 | AA36: 0 | AB36: 0
A37: Ronald Adams | B37: Churned | C37: 43525 | D37: 43952 | E37: 0 | F37: 0 | G37: 1 | H37: 1 | I37: 1 | J37: 1 | K37: 1 | L37: 1 | M37: 1 | N37: 1 | O37: 1 | P37: 1 | Q37: 1 | R37: 1 | S37: 1 | T37: 1 | U37: 0 | V37: 0 | W37: 0 | X37: 0 | Y37: 0 | Z37: 0 | AA37: 0 | AB37: 0
A38: Sarah Baker | B38: Active | C38: 43525 | E38: 0 | F38: 0 | G38: 1 | H38: 1 | I38: 1 | J38: 1 | K38: 1 | L38: 1 | M38: 1 | N38: 1 | O38: 1 | P38: 1 | Q38: 1 | R38: 1 | S38: 1 | T38: 1 | U38: 1 | V38: 1 | W38: 1 | X38: 1 | Y38: 1 | Z38: 1 | AA38: 1 | AB38: 1
A39: Timothy Gonzalez | B39: Churned | C39: 43556 | D39: 43770 | E39: 0 | F39: 0 | G39: 0 | H39: 1 | I39: 1 | J39: 1 | K39: 1 | L39: 1 | M39: 1 | N39: 1 | O39: 0 | P39: 0 | Q39: 0 | R39: 0 | S39: 0 | T39: 0 | U39: 0 | V39: 0 | W39: 0 | X39: 0 | Y39: 0 | Z39: 0 | AA39: 0 | AB39: 0
A40: Jessica Nelson | B40: Active | C40: 43556 | E40: 0 | F40: 0 | G40: 0 | H40: 1 | I40: 1 | J40: 1 | K40: 1 | L40: 1 | M40: 1 | N40: 1 | O40: 1 | P40: 1 | Q40: 1 | R40: 1 | S40: 1 | T40: 1 | U40: 1 | V40: 1 | W40: 1 | X40: 1 | Y40: 1 | Z40: 1 | AA40: 1 | AB40: 1
...

Sheet referencia
A1: Mes de Registro | B1: Nuevos Clientes | C1: =+DATE(2019,1,1) -> 43466 | D1: =+EDATE(C1,1) -> 43497 | E1: =+EDATE(D1,1) -> 43525 | F1: =+EDATE(E1,1) -> 43556 | G1: =+EDATE(F1,1) -> 43586 | H1: =+EDATE(G1,1) -> 43617 | I1: =+EDATE(H1,1) -> 43647 | J1: =+EDATE(I1,1) -> 43678 | K1: =+EDATE(J1,1) -> 43709 | ... Z1: =+EDATE(Y1,1) -> 44166
A2: 43466 | B2: 11 | C2: 11 | D2: 11 | E2: 10 | F2: 10 | G2: 10 | H2: 10 | I2: 10 | J2: 9 | K2: 8 | L2: 8 | M2: 8 | N2: 8 | O2: 8 | P2: 8 | Q2: 8 | R2: 8 | S2: 8 | T2: 8 | U2: 8 | V2: 8 | W2: 7 | X2: 7 | Y2: 7 | Z2: 7
A3: 43497 | B3: 13 | C3: 0 | D3: 13 | E3: 13 | F3: 12 | G3: 11 | H3: 10 | I3: 10 | J3: 10 | K3: 10 | L3: 9 | M3: 8 | N3: 8 | O3: 8 | P3: 8 | Q3: 8 | R3: 8 | S3: 8 | T3: 8 | U3: 8 | V3: 8 | W3: 8 | X3: 8 | Y3: 8 | Z3: 8
A4: 43525 | B4: 13 | C4: 0 | D4: 0 | E4: 13 | F4: 13 | G4: 13 | H4: 13 | I4: 13 | J4: 13 | K4: 12 | L4: 11 | M4: 11 | N4: 11 | O4: 11 | P4: 11 | Q4: 10 | R4: 10 | S4: 7 | T4: 6 | U4: 6 | V4: 6 | W4: 5 | X4: 4 | Y4: 4 | Z4: 4
A5: 43556 | B5: 15 | C5: 0 | D5: 0 | E5: 0 | F5: 15 | G5: 15 | H5: 14 | I5: 14 | J5: 13 | K5: 12 | L5: 12 | M5: 11 | N5: 11 | O5: 9 | P5: 9 | Q5: 9 | R5: 7 | S5: 7 | T5: 7 | U5: 7 | V5: 7 | W5: 7 | X5: 7 | Y5: 7 | Z5: 7
A6: 43586 | B6: 13 | C6: 0 | D6: 0 | E6: 0 | F6: 0 | G6: 13 | H6: 13 | I6: 13 | J6: 12 | K6: 11 | L6: 10 | M6: 10 | N6: 10 | O6: 10 | P6: 9 | Q6: 9 | R6: 9 | S6: 8 | T6: 8 | U6: 6 | V6: 6 | W6: 6 | X6: 6 | Y6: 6 | Z6: 6
A7: 43617 | B7: 11 | C7: 0 | D7: 0 | E7: 0 | F7: 0 | G7: 0 | H7: 11 | I7: 11 | J7: 11 | K7: 10 | L7: 10 | M7: 10 | N7: 9 | O7: 9 | P7: 8 | Q7: 8 | R7: 8 | S7: 8 | T7: 8 | U7: 8 | V7: 8 | W7: 7 | X7: 7 | Y7: 7 | Z7: 6
A8: 43647 | B8: 11 | C8: 0 | D8: 0 | E8: 0 | F8: 0 | G8: 0 | H8: 0 | I8: 11 | J8: 11 | K8: 11 | L8: 11 | M8: 11 | N8: 11 | O8: 10 | P8: 8 | Q8: 8 | R8: 8 | S8: 7 | T8: 7 | U8: 7 | V8: 6 | W8: 6 | X8: 6 | Y8: 5 | Z8: 5
A9: 43678 | B9: 4 | C9: 0 | D9: 0 | E9: 0 | F9: 0 | G9: 0 | H9: 0 | I9: 0 | J9: 4 | K9: 3 | L9: 3 | M9: 3 | N9: 3 | O9: 3 | P9: 3 | Q9: 3 | R9: 3 | S9: 3 | T9: 3 | U9: 3 | V9: 3 | W9: 3 | X9: 3 | Y9: 3 | Z9: 3
A10: 43709 | B10: 8 | C10: 0 | D10: 0 | E10: 0 | F10: 0 | G10: 0 | H10: 0 | I10: 0 | J10: 0 | K10: 8 | L10: 8 | M10: 7 | N10: 7 | O10: 6 | P10: 6 | Q10: 6 | R10: 6 | S10: 6 | T10: 6 | U10: 6 | V10: 6 | W10: 4 | X10: 4 | Y10: 4 | Z10: 4
A11: 43739 | B11: 15 | C11: 0 | D11: 0 | E11: 0 | F11: 0 | G11: 0 | H11: 0 | I11: 0 | J11: 0 | K11: 0 | L11: 15 | M11: 15 | N11: 15 | O11: 15 | P11: 15 | Q11: 14 | R11: 14 | S11: 14 | T11: 14 | U11: 13 | V11: 13 | W11: 13 | X11: 12 | Y11: 11 | Z11: 11
A12: 43770 | B12: 13 | C12: 0 | D12: 0 | E12: 0 | F12: 0 | G12: 0 | H12: 0 | I12: 0 | J12: 0 | K12: 0 | L12: 0 | M12: 13 | N12: 13 | O12: 13 | P12: 13 | Q12: 13 | R12: 12 | S12: 10 | T12: 10 | U12: 10 | V12: 10 | W12: 10 | X12: 10 | Y12: 10 | Z12: 9
A13: 43800 | B13: 6 | C13: 0 | D13: 0 | E13: 0 | F13: 0 | G13: 0 | H13: 0 | I13: 0 | J13: 0 | K13: 0 | L13: 0 | M13: 0 | N13: 6 | O13: 6 | P13: 6 | Q13: 6 | R13: 6 | S13: 6 | T13: 6 | U13: 6 | V13: 6 | W13: 6 | X13: 6 | Y13: 6 | Z13: 6
... A25: 44166 | B25: 16 | C25: 0 | D25: 0 | E25: 0 | F25: 0 | G25: 0 | H25: 0 | I25: 0 | J25: 0 | K25: 0 | L25: 0 | M25: 0 | N25: 0 | O25: 0 | P25: 0 | Q25: 0 | R25: 0 | S25: 0 | T25: 0 | U25: 0 | V25: 0 | W25: 0 | X25: 0 | Y25: 0 | Z25: 16
A26: Total | B26: 330 | C26: 11 | D26: 24 | E26: 36 | F26: 50 | G26: 62 | H26: 71 | I26: 82 | J26: 83 | K26: 85 | L26: 97 | M26: 107 | N26: 112 | O26: 129 | P26: 136 | Q26: 144 | R26: 157 | S26: 175 | T26: 189 | U26: 207 | V26: 230 | W26: 220 | X26: 227 | Y26: 228 | Z26: 233

Sheet retencion_mensual
A1: Mes de Registro | B1: Nuevos Clientes | C1: 01/2019 | D1: 02/2019 | E1: 03/2019 | F1: 04/2019 | G1: 05/2019 | H1: 06/2019 | I1: 07/2019 | J1: 08/2019 | K1: 09/2019 | L1: 10/2019 | M1: 11/2019 | N1: 12/2019 | O1: 01/2020 | P1: 02/2020 | Q1: 03/2020 | R1: 04/2020 | S1: 05/2020 | T1: 06/2020 | U1: 07/2020 | V1: 08/2020 | W1: 09/2020 | X1: 10/2020 | Y1: 11/2020 | Z1: 12/2020
A2: 43466 | B2: 11 | C2: 11 | D2: 11 | E2: 10 | F2: 10 | G2: 10 | H2: 10 | I2: 10 | J2: 9 | K2: 8 | L2: 8 | M2: 8 | N2: 8 | O2: 8 | P2: 8 | Q2: 8 | R2: 8 | S2: 8 | T2: 8 | U2: 8 | V2: 8 | W2: 7 | X2: 7 | Y2: 7 | Z2: 7
A3: 43497 | B3: 13 | C3: 0 | D3: 13 | E3: 13 | F3: 12 | G3: 11 | H3: 10 | I3: 10 | J3: 10 | K3: 10 | L3: 9 | M3: 8 | N3: 8 | O3: 8 | P3: 8 | Q3: 8 | R3: 8 | S3: 8 | T3: 8 | U3: 8 | V3: 8 | W3: 8 | X3: 8 | Y3: 8 | Z3: 8
A4: 43525 | B4: 13 | C4: 0 | D4: 0 | E4: 13 | F4: 13 | G4: 13 | H4: 13 | I4: 13 | J4: 13 | K4: 12 | L4: 11 | M4: 11 | N4: 11 | O4: 11 | P4: 11 | Q4: 10 | R4: 10 | S4: 7 | T4: 6 | U4: 6 | V4: 6 | W4: 5 | X4: 4 | Y4: 4 | Z4: 4
A5: 43556 | B5: 15 | C5: 0 | D5: 0 | E5: 0 | F5: 15 | G5: 15 | H5: 14 | I5: 14 | J5: 13 | K5: 12 | L5: 12 | M5: 11 | N5: 11 | O5: 9 | P5: 9 | Q5: 9 | R5: 7 | S5: 7 | T5: 7 | U5: 7 | V5: 7 | W5: 7 | X5: 7 | Y5: 7 | Z5: 7
A6: 43586 | B6: 13 | C6: 0 | D6: 0 | E6: 0 | F6: 0 | G6: 13 | H6: 13 | I6: 13 | J6: 12 | K6: 11 | L6: 10 | M6: 10 | N6: 10 | O6: 10 | P6: 9 | Q6: 9 | R6: 9 | S6: 8 | T6: 8 | U6: 6 | V6: 6 | W6: 6 | X6: 6 | Y6: 6 | Z6: 6
A7: 43617 | B7: 11 | C7: 0 | D7: 0 | E7: 0 | F7: 0 | G7: 0 | H7: 11 | I7: 11 | J7: 11 | K7: 10 | L7: 10 | M7: 10 | N7: 9 | O7: 9 | P7: 8 | Q7: 8 | R7: 8 | S7: 8 | T7: 8 | U7: 8 | V7: 8 | W7: 7 | X7: 7 | Y7: 7 | Z7: 6
A8: 43647 | B8: 11 | C8: 0 | D8: 0 | E8: 0 | F8: 0 | G8: 0 | H8: 0 | I8: 11 | J8: 11 | K8: 11 | L8: 11 | M8: 11 | N8: 11 | O8: 10 | P8: 8 | Q8: 8 | R8: 8 | S8: 7 | T8: 7 | U8: 7 | V8: 6 | W8: 6 | X8: 6 | Y8: 5 | Z8: 5
A9: 43678 | B9: 4 | C9: 0 | D9: 0 | E9: 0 | F9: 0 | G9: 0 | H9: 0 | I9: 0 | J9: 4 | K9: 3 | L9: 3 | M9: 3 | N9: 3 | O9: 3 | P9: 3 | Q9: 3 | R9: 3 | S9: 3 | T9: 3 | U9: 3 | V9: 3 | W9: 3 | X9: 3 | Y9: 3 | Z9: 3
A10: 43709 | B10: 8 | C10: 0 | D10: 0 | E10: 0 | F10: 0 | G10: 0 | H10: 0 | I10: 0 | J10: 0 | K10: 8 | L10: 8 | M10: 7 | N10: 7 | O10: 6 | P10: 6 | Q10: 6 | R10: 6 | S10: 6 | T10: 6 | U10: 6 | V10: 6 | W10: 4 | X10: 4 | Y10: 4 | Z10: 4
A11: 43739 | B11: 15 | C11: 0 | D11: 0 | E11: 0 | F11: 0 | G11: 0 | H11: 0 | I11: 0 | J11: 0 | K11: 0 | L11: 15 | M11: 15 | N11: 15 | O11: 15 | P11: 15 | Q11: 14 | R11: 14 | S11: 14 | T11: 14 | U11: 13 | V11: 13 | W11: 13 | X11: 12 | Y11: 11 | Z11: 11
A12: 43770 | B12: 13 | C12: 0 | D12: 0 | E12: 0 | F12: 0 | G12: 0 | H12: 0 | I12: 0 | J12: 0 | K12: 0 | L12: 0 | M12: 13 | N12: 13 | O12: 13 | P12: 13 | Q12: 13 | R12: 12 | S12: 10 | T12: 10 | U12: 10 | V12: 10 | W12: 10 | X12: 10 | Y12: 10 | Z12: 9
A13: 43800 | B13: 6 | C13: 0 | D13: 0 | E13: 0 | F13: 0 | G13: 0 | H13: 0 | I13: 0 | J13: 0 | K13: 0 | L13: 0 | M13: 0 | N13: 6 | O13: 6 | P13: 6 | Q13: 6 | R13: 6 | S13: 6 | T13: 6 | U13: 6 | V13: 6 | W13: 6 | X13: 6 | Y13: 6 | Z13: 6
... A25: 44166 | B25: 16 | C25: 0 | D25: 0 | E25: 0 | F25: 0 | G25: 0 | H25: 0 | I25: 0 | J25: 0 | K25: 0 | L25: 0 | M25: 0 | N25: 0 | O25: 0 | P25: 0 | Q25: 0 | R25: 0 | S25: 0 | T25: 0 | U25: 0 | V25: 0 | W25: 0 | X25: 0 | Y25: 0 | Z25: 16
A26: Total | B26: 330 | C26: 11 | D26: 24 | E26: 36 | F26: 50 | G26: 62 | H26: 71 | I26: 82 | J26: 83 | K26: 85 | L26: 97 | M26: 107 | N26: 112 | O26: 129 | P26: 136 | Q26: 144 | R26: 157 | S26: 175 | T26: 189 | U26: 207 | V26: 230 | W26: 220 | X26: 227 | Y26: 228 | Z26: 233
A33: Mes de Registro | B33: Nuevos Clientes | C33: mes 1 | D33: mes 2 | E33: mes 3 | F33: mes 4 | G33: mes 5 | H33: mes 6 | I33: mes 7 | J33: mes 8 | K33: mes 9 | L33: mes 10 | M33: mes 11 | N33: mes 12 | O33: mes 13 | P33: mes 14 | Q33: mes 15 | R33: mes 16 | S33: mes 17 | T33: mes 18 | U33: mes 19 | V33: mes 20 | W33: mes 21 | X33: mes 22 | Y33: mes 23 | Z33: mes 24
A34: 43466 | B34: 11 | C34: =IFERROR((INDEX(referencia!$C2:$Z2,1,(MATCH(referencia!$A2,referencia!$C$1:$Z$1,0)+COLUMNS(referencia!$C:C)-1)))," ") -> 11 | D34: =IFERROR((INDEX(referencia!$C2:$Z2,1,(MATCH(referencia!$A2,referencia!$C$1:$Z$1,0)+COLUMNS(referencia!$C:D)-1)))," ") -> 11 | E34: =IFERROR((INDEX(referencia!$C2:$Z2,1,(MATCH(referencia!$A2,referencia!$C$1:$Z$1,0)+COLUMNS(referencia!$C:E)-1)))," ") -> 10 | F34: =IFERROR((INDEX(referencia!$C2:$Z2,1,(MATCH(referencia!$A2,referencia!$C$1:$Z$1,0)+COLUMNS(referencia!$C:F)-1)))," ") -> 10 | G34: =IFERROR((INDEX(referencia!$C2:$Z2,1,(MATCH(referencia!$A2,referencia!$C$1:$Z$1,0)+COLUMNS(referencia!$C:G)-1)))," ") -> 10 | H34: =IFERROR((INDEX(referencia!$C2:$Z2,1,(MATCH(referencia!$A2,referencia!$C$1:$Z$1,0)+COLUMNS(referencia!$C:H)-1)))," ") -> 10 | I34: =IFERROR((INDEX(referencia!$C2:$Z2,1,(MATCH(referencia!$A2,referencia!$C$1:$Z$1,0)+COLUMNS(referencia!$C:I)-1)))," ") -> 10 | J34: =IFERROR((INDEX(referencia!$C2:$Z2,1,(MATCH(referencia!$A2,referencia!$C$1:$Z$1,0)+COLUMNS(referencia!$C:J)-1)))," ") -> 9 | K34: =IFERROR((INDEX(referencia!$C2:$Z2,1,(MATCH(referencia!$A2,referencia!$C$1:$Z$1,0)+COLUMNS(referencia!$C:K)-1)))," ") -> 8 | L34: =IFERROR((INDEX(referencia!$C2:$Z2,1,(MATCH(referencia!$A2,referencia!$C$1:$Z$1,0)+COLUMNS(referencia!$C:L)-1)))," ") -> 8 | M34: =IFERROR((INDEX(referencia!$C2:$Z2,1,(MATCH(referencia!$A2,referencia!$C$1:$Z$1,0)+COLUMNS(referencia!$C:M)-1)))," ") -> 8 | N34: =IFERROR((INDEX(referencia!$C2:$Z2,1,(MATCH(referencia!$A2,referencia!$C$1:$Z$1,0)+COLUMNS(referencia!$C:N)-1)))," ") -> 8 | O34: =IFERROR((INDEX(referencia!$C2:$Z2,1,(MATCH(referencia!$A2,referencia!$C$1:$Z$1,0)+COLUMNS(referencia!$C:O)-1)))," ") -> 8 | P34: =IFERROR((INDEX(referencia!$C2:$Z2,1,(MATCH(referencia!$A2,referencia!$C$1:$Z$1,0)+COLUMNS(referencia!$C:P)-1)))," ") -> 8 | Q34: =IFERROR((INDEX(referencia!$C2:$Z2,1,(MATCH(referencia!$A2,referencia!$C$1:$Z$1,0)+COLUMNS(referencia!$C:Q)-1)))," ") -> 8 | R34: =IFERROR((INDEX(referencia!$C2:$Z2,1,(MATCH(referencia!$A2,referencia!$C$1:$Z$1,0)+COLUMNS(referencia!$C:R)-1)))," ") -> 8 | S34: =IFERROR((INDEX(referencia!$C2:$Z2,1,(MATCH(referencia!$A2,referencia!$C$1:$Z$1,0)+COLUMNS(referencia!$C:S)-1)))," ") -> 8 | T34: =IFERROR((INDEX(referencia!$C2:$Z2,1,(MATCH(referencia!$A2,referencia!$C$1:$Z$1,0)+COLUMNS(referencia!$C:T)-1)))," ") -> 8 | U34: =IFERROR((INDEX(referencia!$C2:$Z2,1,(MATCH(referencia!$A2,referencia!$C$1:$Z$1,0)+COLUMNS(referencia!$C:U)-1)))," ") -> 8 | V34: =IFERROR((INDEX(referencia!$C2:$Z2,1,(MATCH(referencia!$A2,referencia!$C$1:$Z$1,0)+COLUMNS(referencia!$C:V)-1)))," ") -> 8 | W34: =IFERROR((INDEX(referencia!$C2:$Z2,1,(MATCH(referencia!$A2,referencia!$C$1:$Z$1,0)+COLUMNS(referencia!$C:W)-1)))," ") -> 7 | X34: =IFERROR((INDEX(referencia!$C2:$Z2,1,(MATCH(referencia!$A2,referencia!$C$1:$Z$1,0)+COLUMNS(referencia!$C:X)-1)))," ") -> 7 | Y34: =IFERROR((INDEX(referencia!$C2:$Z2,1,(MATCH(referencia!$A2,referencia!$C$1:$Z$1,0)+COLUMNS(referencia!$C:Y)-1)))," ") -> 7 | Z34: =IFERROR((INDEX(referencia!$C2:$Z2,1,(MATCH(referencia!$A2,referencia!$C$1:$Z$1,0)+COLUMNS(referencia!$C:Z)-1)))," ") -> 7
A35: 43497 | B35: 13 | C35: =IFERROR((INDEX(referencia!$C3:$Z3,1,(MATCH(referencia!$A3,referencia!$C$1:$Z$1,0)+COLUMNS(referencia!$C:C)-1)))," ") -> 13 | D35: =IFERROR((INDEX(referencia!$C3:$Z3,1,(MATCH(referencia!$A3,referencia!$C$1:$Z$1,0)+COLUMNS(referencia!$C:D)-1)))," ") -> 13 | E35: =IFERROR((INDEX(referencia!$C3:$Z3,1,(MATCH(referencia!$A3,referencia!$C$1:$Z$1,0)+COLUMNS(referencia!$C:E)-1)))," ") -> 12 | F35: =IFERROR((INDEX(referencia!$C3:$Z3,1,(MATCH(referencia!$A3,referencia!$C$1:$Z$1,0)+COLUMNS(referencia!$C:F)-1)))," ") -> 11 | G35: =IFERROR((INDEX(referencia!$C3:$Z3,1,(MATCH(referencia!$A3,referencia!$C$1:$Z$1,0)+COLUMNS(referencia!$C:G)-1)))," ") -> 10 | H35: =IFERROR((INDEX(referencia!$C3:$Z3,1,(MATCH(referencia!$A3,referencia!$C$1:$Z$1,0)+COLUMNS(referencia!$C:H)-1)))," ") -> 10 | I35: =IFERROR((INDEX(referencia!$C3:$Z3,1,(MATCH(referencia!$A3,referencia!$C$1:$Z$1,0)+COLUMNS(referencia!$C:I)-1)))," ") -> 10 | J35: =IFERROR((INDEX(referencia!$C3:$Z3,1,(MATCH(referencia!$A3,referencia!$C$1:$Z$1,0)+COLUMNS(referencia!$C:J)-1)))," ") -> 10 | K35: =IFERROR((INDEX(referencia!$C3:$Z3,1,(MATCH(referencia!$A3,referencia!$C$1:$Z$1,0)+COLUMNS(referencia!$C:K)-1)))," ") -> 9 | L35: =IFERROR((INDEX(referencia!$C3:$Z3,1,(MATCH(referencia!$A3,referencia!$C$1:$Z$1,0)+COLUMNS(referencia!$C:L)-1)))," ") -> 8 | M35: =IFERROR((INDEX(referencia!$C3:$Z3,1,(MATCH(referencia!$A3,referencia!$C$1:$Z$1,0)+COLUMNS(referencia!$C:M)-1)))," ") -> 8 | N35: =IFERROR((INDEX(referencia!$C3:$Z3,1,(MATCH(referencia!$A3,referencia!$C$1:$Z$1,0)+COLUMNS(referencia!$C:N)-1)))," ") -> 8 | O35: =IFERROR((INDEX(referencia!$C3:$Z3,1,(MATCH(referencia!$A3,referencia!$C$1:$Z$1,0)+COLUMNS(referencia!$C:O)-1)))," ") -> 8 | P35: =IFERROR((INDEX(referencia!$C3:$Z3,1,(MATCH(referencia!$A3,referencia!$C$1:$Z$1,0)+COLUMNS(referencia!$C:P)-1)))," ") -> 8 | Q35: =IFERROR((INDEX(referencia!$C3:$Z3,1,(MATCH(referencia!$A3,referencia!$C$1:$Z$1,0)+COLUMNS(referencia!$C:Q)-1)))," ") -> 8 | R35: =IFERROR((INDEX(referencia!$C3:$Z3,1,(MATCH(referencia!$A3,referencia!$C$1:$Z$1,0)+COLUMNS(referencia!$C:R)-1)))," ") -> 8 | S35: =IFERROR((INDEX(referencia!$C3:$Z3,1,(MATCH(referencia!$A3,referencia!$C$1:$Z$1,0)+COLUMNS(referencia!$C:S)-1)))," ") -> 8 | T35: =IFERROR((INDEX(referencia!$C3:$Z3,1,(MATCH(referencia!$A3,referencia!$C$1:$Z$1,0)+COLUMNS(referencia!$C:T)-1)))," ") -> 8 | U35: =IFERROR((INDEX(referencia!$C3:$Z3,1,(MATCH(referencia!$A3,referencia!$C$1:$Z$1,0)+COLUMNS(referencia!$C:U)-1)))," ") -> 8 | V35: =IFERROR((INDEX(referencia!$C3:$Z3,1,(MATCH(referencia!$A3,referencia!$C$1:$Z$1,0)+COLUMNS(referencia!$C:V)-1)))," ") -> 8 | W35: =IFERROR((INDEX(referencia!$C3:$Z3,1,(MATCH(referencia!$A3,referencia!$C$1:$Z$1,0)+COLUMNS(referencia!$C:W)-1)))," ") -> 8 | X35: =IFERROR((INDEX(referencia!$C3:$Z3,1,(MATCH(referencia!$A3,referencia!$C$1:$Z$1,0)+COLUMNS(referencia!$C:X)-1)))," ") -> 8 | Y35: =IFERROR((INDEX(referencia!$C3:$Z3,1,(MATCH(referencia!$A3,referencia!$C$1:$Z$1,0)+COLUMNS(referencia!$C:Y)-1)))," ") -> 8 | Z35: =IFERROR((INDEX(referencia!$C3:$Z3,1,(MATCH(referencia!$A3,referencia!$C$1:$Z$1,0)+COLUMNS(referencia!$C:Z)-1)))," ")
A36: 43525 | B36: 13 | C36: =IFERROR((INDEX(referencia!$C4:$Z4,1,(MATCH(referencia!$A4,referencia!$C$1:$Z$1,0)+COLUMNS(referencia!$C:C)-1)))," ") -> 13 | D36: =IFERROR((INDEX(referencia!$C4:$Z4,1,(MATCH(referencia!$A4,referencia!$C$1:$Z$1,0)+COLUMNS(referencia!$C:D)-1)))," ") -> 13 | E36: =IFERROR((INDEX(referencia!$C4:$Z4,1,(MATCH(referencia!$A4,referencia!$C$1:$Z$1,0)+COLUMNS(referencia!$C:E)-1)))," ") -> 13 | F36: =IFERROR((INDEX(referencia!$C4:$Z4,1,(MATCH(referencia!$A4,referencia!$C$1:$Z$1,0)+COLUMNS(referencia!$C:F)-1)))," ") -> 13 | G36: =IFERROR((INDEX(referencia!$C4:$Z4,1,(MATCH(referencia!$A4,referencia!$C$1:$Z$1,0)+COLUMNS(referencia!$C:G)-1)))," ") -> 13 | H36: =IFERROR((INDEX(referencia!$C4:$Z4,1,(MATCH(referencia!$A4,referencia!$C$1:$Z$1,0)+COLUMNS(referencia!$C:H)-1)))," ") -> 13 | I36: =IFERROR((INDEX(referencia!$C4:$Z4,1,(MATCH(referencia!$A4,referencia!$C$1:$Z$1,0)+COLUMNS(referencia!$C:I)-1)))," ") -> 12 | J36: =IFERROR((INDEX(referencia!$C4:$Z4,1,(MATCH(referencia!$A4,referencia!$C$1:$Z$1,0)+COLUMNS(referencia!$C:J)-1)))," ") -> 11 | K36: =IFERROR((INDEX(referencia!$C4:$Z4,1,(MATCH(referencia!$A4,referencia!$C$1:$Z$1,0)+COLUMNS(referencia!$C:K)-1)))," ") -> 11 | L36: =IFERROR((INDEX(referencia!$C4:$Z4,1,(MATCH(referencia!$A4,referencia!$C$1:$Z$1,0)+COLUMNS(referencia!$C:L)-1)))," ") -> 11 | M36: =IFERROR((INDEX(referencia!$C4:$Z4,1,(MATCH(referencia!$A4,referencia!$C$1:$Z$1,0)+COLUMNS(referencia!$C:M)-1)))," ") -> 11 | N36: =IFERROR((INDEX(referencia!$C4:$Z4,1,(MATCH(referencia!$A4,referencia!$C$1:$Z$1,0)+COLUMNS(referencia!$C:N)-1)))," ") -> 11 | O36: =IFERROR((INDEX(referencia!$C4:$Z4,1,(MATCH(referencia!$A4,referencia!$C$1:$Z$1,0)+COLUMNS(referencia!$C:O)-1)))," ") -> 10 | P36: =IFERROR((INDEX(referencia!$C4:$Z4,1,(MATCH(referencia!$A4,referencia!$C$1:$Z$1,0)+COLUMNS(referencia!$C:P)-1)))," ") -> 10 | Q36: =IFERROR((INDEX(referencia!$C4:$Z4,1,(MATCH(referencia!$A4,referencia!$C$1:$Z$1,0)+COLUMNS(referencia!$C:Q)-1)))," ") -> 7 | R36: =IFERROR((INDEX(referencia!$C4:$Z4,1,(MATCH(referencia!$A4,referencia!$C$1:$Z$1,0)+COLUMNS(referencia!$C:R)-1)))," ") -> 6 | S36: =IFERROR((INDEX(referencia!$C4:$Z4,1,(MATCH(referencia!$A4,referencia!$C$1:$Z$1,0)+COLUMNS(referencia!$C:S)-1)))," ") -> 6 | T36: =IFERROR((INDEX(referencia!$C4:$Z4,1,(MATCH(referencia!$A4,referencia!$C$1:$Z$1,0)+COLUMNS(referencia!$C:T)-1)))," ") -> 6 | U36: =IFERROR((INDEX(referencia!$C4:$Z4,1,(MATCH(referencia!$A4,referencia!$C$1:$Z$1,0)+COLUMNS(referencia!$C:U)-1)))," ") -> 5 | V36: =IFERROR((INDEX(referencia!$C4:$Z4,1,(MATCH(referencia!$A4,referencia!$C$1:$Z$1,0)+COLUMNS(referencia!$C:V)-1)))," ") -> 4 | W36: =IFERROR((INDEX(referencia!$C4:$Z4,1,(MATCH(referencia!$A4,referencia!$C$1:$Z$1,0)+COLUMNS(referencia!$C:W)-1)))," ") -> 4 | X36: =IFERROR((INDEX(referencia!$C4:$Z4,1,(MATCH(referencia!$A4,referencia!$C$1:$Z$1,0)+COLUMNS(referencia!$C:X)-1)))," ") -> 4 | Y36: =IFERROR((INDEX(referencia!$C4:$Z4,1,(MATCH(referencia!$A4,referencia!$C$1:$Z$1,0)+COLUMNS(referencia!$C:Y)-1)))," ") | Z36: =IFERROR((INDEX(referencia!$C4:$Z4,1,(MATCH(referencia!$A4,referencia!$C$1:$Z$1,0)+COLUMNS(referencia!$C:Z)-1)))," ")
A37: 43556 | B37: 15 | C37: =IFERROR((INDEX(referencia!$C5:$Z5,1,(MATCH(referencia!$A5,referencia!$C$1:$Z$1,0)+COLUMNS(referencia!$C:C)-1)))," ") -> 15 | D37: =IFERROR((INDEX(referencia!$C5:$Z5,1,(MATCH(referencia!$A5,referencia!$C$1:$Z$1,0)+COLUMNS(referencia!$C:D)-1)))," ") -> 15 | E37: =IFERROR((INDEX(referencia!$C5:$Z5,1,(MATCH(referencia!$A5,referencia!$C$1:$Z$1,0)+COLUMNS(referencia!$C:E)-1)))," ") -> 14 | F37: =IFERROR((INDEX(referencia!$C5:$Z5,1,(MATCH(referencia!$A5,referencia!$C$1:$Z$1,0)+COLUMNS(referencia!$C:F)-1)))," ") -> 14 | G37: =IFERROR((INDEX(referencia!$C5:$Z5,1,(MATCH(referencia!$A5,referencia!$C$1:$Z$1,0)+COLUMNS(referencia!$C:G)-1)))," ") -> 13 | H37: =IFERROR((INDEX(referencia!$C5:$Z5,1,(MATCH(referencia!$A5,referencia!$C$1:$Z$1,0)+COLUMNS(referencia!$C:H)-1)))," ") -> 12 | I37: =IFERROR((INDEX(referencia!$C5:$Z5,1,(MATCH(referencia!$A5,referencia!$C$1:$Z$1,0)+COLUMNS(referencia!$C:I)-1)))," ") -> 12 | J37: =IFERROR((INDEX(referencia!$C5:$Z5,1,(MATCH(referencia!$A5,referencia!$C$1:$Z$1,0)+COLUMNS(referencia!$C:J)-1)))," ") -> 11 | K37: =IFERROR((INDEX(referencia!$C5:$Z5,1,(MATCH(referencia!$A5,referencia!$C$1:$Z$1,0)+COLUMNS(referencia!$C:K)-1)))," ") -> 11 | L37: =IFERROR((INDEX(referencia!$C5:$Z5,1,(MATCH(referencia!$A5,referencia!$C$1:$Z$1,0)+COLUMNS(referencia!$C:L)-1)))," ") -> 9 | M37: =IFERROR((INDEX(referencia!$C5:$Z5,1,(MATCH(referencia!$A5,referencia!$C$1:$Z$1,0)+COLUMNS(referencia!$C:M)-1)))," ") -> 9 | N37: =IFERROR((INDEX(referencia!$C5:$Z5,1,(MATCH(referencia!$A5,referencia!$C$1:$Z$1,0)+COLUMNS(referencia!$C:N)-1)))," ") -> 9 | O37: =IFERROR((INDEX(referencia!$C5:$Z5,1,(MATCH(referencia!$A5,referencia!$C$1:$Z$1,0)+COLUMNS(referencia!$C:O)-1)))," ") -> 7 | P37: =IFERROR((INDEX(referencia!$C5:$Z5,1,(MATCH(referencia!$A5,referencia!$C$1:$Z$1,0)+COLUMNS(referencia!$C:P)-1)))," ") -> 7 | Q37: =IFERROR((INDEX(referencia!$C5:$Z5,1,(MATCH(referencia!$A5,referencia!$C$1:$Z$1,0)+COLUMNS(referencia!$C:Q)-1)))," ") -> 7 | R37: =IFERROR((INDEX(referencia!$C5:$Z5,1,(MATCH(referencia!$A5,referencia!$C$1:$Z$1,0)+COLUMNS(referencia!$C:R)-1)))," ") -> 7 | S37: =IFERROR((INDEX(referencia!$C5:$Z5,1,(MATCH(referencia!$A5,referencia!$C$1:$Z$1,0)+COLUMNS(referencia!$C:S)-1)))," ") -> 7 | T37: =IFERROR((INDEX(referencia!$C5:$Z5,1,(MATCH(referencia!$A5,referencia!$C$1:$Z$1,0)+COLUMNS(referencia!$C:T)-1)))," ") -> 7 | U37: =IFERROR((INDEX(referencia!$C5:$Z5,1,(MATCH(referencia!$A5,referencia!$C$1:$Z$1,0)+COLUMNS(referencia!$C:U)-1)))," ") -> 7 | V37: =IFERROR((INDEX(referencia!$C5:$Z5,1,(MATCH(referencia!$A5,referencia!$C$1:$Z$1,0)+COLUMNS(referencia!$C:V)-1)))," ") -> 7 | W37: =IFERROR((INDEX(referencia!$C5:$Z5,1,(MATCH(referencia!$A5,referencia!$C$1:$Z$1,0)+COLUMNS(referencia!$C:W)-1)))," ") -> 7 | X37: =IFERROR((INDEX(referencia!$C5:$Z5,1,(MATCH(referencia!$A5,referencia!$C$1:$Z$1,0)+COLUMNS(referencia!$C:X)-1)))," ") | Y37: =IFERROR((INDEX(referencia!$C5:$Z5,1,(MATCH(referencia!$A5,referencia!$C$1:$Z$1,0)+COLUMNS(referencia!$C:Y)-1)))," ") | Z37: =IFERROR((INDEX(referencia!$C5:$Z5,1,(MATCH(referencia!$A5,referencia!$C$1:$Z$1,0)+COLUMNS(referencia!$C:Z)-1)))," ")
A38: 43586 | B38: 13 | C38: =IFERROR((INDEX(referencia!$C6:$Z6,1,(MATCH(referencia!$A6,referencia!$C$1:$Z$1,0)+COLUMNS(referencia!$C:C)-1)))," ") -> 13 | D38: =IFERROR((INDEX(referencia!$C6:$Z6,1,(MATCH(referencia!$A6,referencia!$C$1:$Z$1,0)+COLUMNS(referencia!$C:D)-1)))," ") -> 13 | E38: =IFERROR((INDEX(referencia!$C6:$Z6,1,(MATCH(referencia!$A6,referencia!$C$1:$Z$1,0)+COLUMNS(referencia!$C:E)-1)))," ") -> 13 | F38: =IFERROR((INDEX(referencia!$C6:$Z6,1,(MATCH(referencia!$A6,referencia!$C$1:$Z$1,0)+COLUMNS(referencia!$C:F)-1)))," ") -> 12 | G38: =IFERROR((INDEX(referencia!$C6:$Z6,1,(MATCH(referencia!$A6,referencia!$C$1:$Z$1,0)+COLUMNS(referencia!$C:G)-1)))," ") -> 11 | H38: =IFERROR((INDEX(referencia!$C6:$Z6,1,(MATCH(referencia!$A6,referencia!$C$1:$Z$1,0)+COLUMNS(referencia!$C:H)-1)))," ") -> 10 | I38: =IFERROR((INDEX(referencia!$C6:$Z6,1,(MATCH(referencia!$A6,referencia!$C$1:$Z$1,0)+COLUMNS(referencia!$C:I)-1)))," ") -> 10 | J38: =IFERROR((INDEX(referencia!$C6:$Z6,1,(MATCH(referencia!$A6,referencia!$C$1:$Z$1,0)+COLUMNS(referencia!$C:J)-1)))," ") -> 10 | K38: =IFERROR((INDEX(referencia!$C6:$Z6,1,(MATCH(referencia!$A6,referencia!$C$1:$Z$1,0)+COLUMNS(referencia!$C:K)-1)))," ") -> 10 | L38: =IFERROR((INDEX(referencia!$C6:$Z6,1,(MATCH(referencia!$A6,referencia!$C$1:$Z$1,0)+COLUMNS(referencia!$C:L)-1)))," ") -> 9 | M38: =IFERROR((INDEX(referencia!$C6:$Z6,1,(MATCH(referencia!$A6,referencia!$C$1:$Z$1,0)+COLUMNS(referencia!$C:M)-1)))," ") -> 9 | N38: =IFERROR((INDEX(referencia!$C6:$Z6,1,(MATCH(referencia!$A6,referencia!$C$1:$Z$1,0)+COLUMNS(referencia!$C:N)-1)))," ") -> 9 | O38: =IFERROR((INDEX(referencia!$C6:$Z6,1,(MATCH(referencia!$A6,referencia!$C$1:$Z$1,0)+COLUMNS(referencia!$C:O)-1)))," ") -> 8 | P38: =IFERROR((INDEX(referencia!$C6:$Z6,1,(MATCH(referencia!$A6,referencia!$C$1:$Z$1,0)+COLUMNS(referencia!$C:P)-1)))," ") -> 8 | Q38: =IFERROR((INDEX(referencia!$C6:$Z6,1,(MATCH(referencia!$A6,referencia!$C$1:$Z$1,0)+COLUMNS(referencia!$C:Q)-1)))," ") -> 6 | R38: =IFERROR((INDEX(referencia!$C6:$Z6,1,(MATCH(referencia!$A6,referencia!$C$1:$Z$1,0)+COLUMNS(referencia!$C:R)-1)))," ") -> 6 | S38: =IFERROR((INDEX(referencia!$C6:$Z6,1,(MATCH(referencia!$A6,referencia!$C$1:$Z$1,0)+COLUMNS(referencia!$C:S)-1)))," ") -> 6 | T38: =IFERROR((INDEX(referencia!$C6:$Z6,1,(MATCH(referencia!$A6,referencia!$C$1:$Z$1,0)+COLUMNS(referencia!$C:T)-1)))," ") -> 6 | U38: =IFERROR((INDEX(referencia!$C6:$Z6,1,(MATCH(referencia!$A6,referencia!$C$1:$Z$1,0)+COLUMNS(referencia!$C:U)-1)))," ") -> 6 | V38: =IFERROR((INDEX(referencia!$C6:$Z6,1,(MATCH(referencia!$A6,referencia!$C$1:$Z$1,0)+COLUMNS(referencia!$C:V)-1)))," ") -> 6 | W38: =IFERROR((INDEX(referencia!$C6:$Z6,1,(MATCH(referencia!$A6,referencia!$C$1:$Z$1,0)+COLUMNS(referencia!$C:W)-1)))," ") | X38: =IFERROR((INDEX(referencia!$C6:$Z6,1,(MATCH(referencia!$A6,referencia!$C$1:$Z$1,0)+COLUMNS(referencia!$C:X)-1)))," ") | Y38: =IFERROR((INDEX(referencia!$C6:$Z6,1,(MATCH(referencia!$A6,referencia!$C$1:$Z$1,0)+COLUMNS(referencia!$C:Y)-1)))," ") | Z38: =IFERROR((INDEX(referencia!$C6:$Z6,1,(MATCH(referencia!$A6,referencia!$C$1:$Z$1,0)+COLUMNS(referencia!$C:Z)-1)))," ")
A39: 43617 | B39: 11 | C39: =IFERROR((INDEX(referencia!$C7:$Z7,1,(MATCH(referencia!$A7,referencia!$C$1:$Z$1,0)+COLUMNS(referencia!$C:C)-1)))," ") -> 11 | D39: =IFERROR((INDEX(referencia!$C7:$Z7,1,(MATCH(referencia!$A7,referencia!$C$1:$Z$1,0)+COLUMNS(referencia!$C:D)-1)))," ") -> 11 | E39: =IFERROR((INDEX(referencia!$C7:$Z7,1,(MATCH(referencia!$A7,referencia!$C$1:$Z$1,0)+COLUMNS(referencia!$C:E)-1)))," ") -> 11 | F39: =IFERROR((INDEX(referencia!$C7:$Z7,1,(MATCH(referencia!$A7,referencia!$C$1:$Z$1,0)+COLUMNS(referencia!$C:F)-1)))," ") -> 10 | G39: =IFERROR((INDEX(referencia!$C7:$Z7,1,(MATCH(referencia!$A7,referencia!$C$1:$Z$1,0)+COLUMNS(referencia!$C:G)-1)))," ") -> 10 | H39: =IFERROR((INDEX(referencia!$C7:$Z7,1,(MATCH(referencia!$A7,referencia!$C$1:$Z$1,0)+COLUMNS(referencia!$C:H)-1)))," ") -> 10 | I39: =IFERROR((INDEX(referencia!$C7:$Z7,1,(MATCH(referencia!$A7,referencia!$C$1:$Z$1,0)+COLUMNS(referencia!$C:I)-1)))," ") -> 9 | J39: =IFERROR((INDEX(referencia!$C7:$Z7,1,(MATCH(referencia!$A7,referencia!$C$1:$Z$1,0)+COLUMNS(referencia!$C:J)-1)))," ") -> 9 | K39: =IFERROR((INDEX(referencia!$C7:$Z7,1,(MATCH(referencia!$A7,referencia!$C$1:$Z$1,0)+COLUMNS(referencia!$C:K)-1)))," ") -> 8 | L39: =IFERROR((INDEX(referencia!$C7:$Z7,1,(MATCH(referencia!$A7,referencia!$C$1:$Z$1,0)+COLUMNS(referencia!$C:L)-1)))," ") -> 8 | M39: =IFERROR((INDEX(referencia!$C7:$Z7,1,(MATCH(referencia!$A7,referencia!$C$1:$Z$1,0)+COLUMNS(referencia!$C:M)-1)))," ") -> 8 | N39: =IFERROR((INDEX(referencia!$C7:$Z7,1,(MATCH(referencia!$A7,referencia!$C$1:$Z$1,0)+COLUMNS(referencia!$C:N)-1)))," ") -> 8 | O39: =IFERROR((INDEX(referencia!$C7:$Z7,1,(MATCH(referencia!$A7,referencia!$C$1:$Z$1,0)+COLUMNS(referencia!$C:O)-1)))," ") -> 8 | P39: =IFERROR((INDEX(referencia!$C7:$Z7,1,(MATCH(referencia!$A7,referencia!$C$1:$Z$1,0)+COLUMNS(referencia!$C:P)-1)))," ") -> 8 | Q39: =IFERROR((INDEX(referencia!$C7:$Z7,1,(MATCH(referencia!$A7,referencia!$C$1:$Z$1,0)+COLUMNS(referencia!$C:Q)-1)))," ") -> 8 | R39: =IFERROR((INDEX(referencia!$C7:$Z7,1,(MATCH(referencia!$A7,referencia!$C$1:$Z$1,0)+COLUMNS(referencia!$C:R)-1)))," ") -> 7 | S39: =IFERROR((INDEX(referencia!$C7:$Z7,1,(MATCH(referencia!$A7,referencia!$C$1:$Z$1,0)+COLUMNS(referencia!$C:S)-1)))," ") -> 7 | T39: =IFERROR((INDEX(referencia!$C7:$Z7,1,(MATCH(referencia!$A7,referencia!$C$1:$Z$1,0)+COLUMNS(referencia!$C:T)-1)))," ") -> 7 | U39: =IFERROR((INDEX(referencia!$C7:$Z7,1,(MATCH(referencia!$A7,referencia!$C$1:$Z$1,0)+COLUMNS(referencia!$C:U)-1)))," ") -> 6 | V39: =IFERROR((INDEX(referencia!$C7:$Z7,1,(MATCH(referencia!$A7,referencia!$C$1:$Z$1,0)+COLUMNS(referencia!$C:V)-1)))," ") | W39: =IFERROR((INDEX(referencia!$C7:$Z7,1,(MATCH(referencia!$A7,referencia!$C$1:$Z$1,0)+COLUMNS(referencia!$C:W)-1)))," ") | X39: =IFERROR((INDEX(referencia!$C7:$Z7,1,(MATCH(referencia!$A7,referencia!$C$1:$Z$1,0)+COLUMNS(referencia!$C:X)-1)))," ") | Y39: =IFERROR((INDEX(referencia!$C7:$Z7,1,(MATCH(referencia!$A7,referencia!$C$1:$Z$1,0)+COLUMNS(referencia!$C:Y)-1)))," ") | Z39: =IFERROR((INDEX(referencia!$C7:$Z7,1,(MATCH(referencia!$A7,referencia!$C$1:$Z$1,0)+COLUMNS(referencia!$C:Z)-1)))," ")
A40: 43647 | B40: 11 | C40: =IFERROR((INDEX(referencia!$C8:$Z8,1,(MATCH(referencia!$A8,referencia!$C$1:$Z$1,0)+COLUMNS(referencia!$C:C)-1)))," ") -> 11 | D40: =IFERROR((INDEX(referencia!$C8:$Z8,1,(MATCH(referencia!$A8,referencia!$C$1:$Z$1,0)+COLUMNS(referencia!$C:D)-1)))," ") -> 11 | E40: =IFERROR((INDEX(referencia!$C8:$Z8,1,(MATCH(referencia!$A8,referencia!$C$1:$Z$1,0)+COLUMNS(referencia!$C:E)-1)))," ") -> 11 | F40: =IFERROR((INDEX(referencia!$C8:$Z8,1,(MATCH(referencia!$A8,referencia!$C$1:$Z$1,0)+COLUMNS(referencia!$C:F)-1)))," ") -> 11 | G40: =IFERROR((INDEX(referencia!$C8:$Z8,1,(MATCH(referencia!$A8,referencia!$C$1:$Z$1,0)+COLUMNS(referencia!$C:G)-1)))," ") -> 11 | H40: =IFERROR((INDEX(referencia!$C8:$Z8,1,(MATCH(referencia!$A8,referencia!$C$1:$Z$1,0)+COLUMNS(referencia!$C:H)-1)))," ") -> 11 | I40: =IFERROR((INDEX(referencia!$C8:$Z8,1,(MATCH(referencia!$A8,referencia!$C$1:$Z$1,0)+COLUMNS(referencia!$C:I)-1)))," ") -> 10 | J40: =IFERROR((INDEX(referencia!$C8:$Z8,1,(MATCH(referencia!$A8,referencia!$C$1:$Z$1,0)+COLUMNS(referencia!$C:J)-1)))," ") -> 8 | K40: =IFERROR((INDEX(referencia!$C8:$Z8,1,(MATCH(referencia!$A8,referencia!$C$1:$Z$1,0)+COLUMNS(referencia!$C:K)-1)))," ") -> 8 | L40: =IFERROR((INDEX(referencia!$C8:$Z8,1,(MATCH(referencia!$A8,referencia!$C$1:$Z$1,0)+COLUMNS(referencia!$C:L)-1)))," ") -> 8 | M40: =IFERROR((INDEX(referencia!$C8:$Z8,1,(MATCH(referencia!$A8,referencia!$C$1:$Z$1,0)+COLUMNS(referencia!$C:M)-1)))," ") -> 7 | N40: =IFERROR((INDEX(referencia!$C8:$Z8,1,(MATCH(referencia!$A8,referencia!$C$1:$Z$1,0)+COLUMNS(referencia!$C:N)-1)))," ") -> 7 | O40: =IFERROR((INDEX(referencia!$C8:$Z8,1,(MATCH(referencia!$A8,referencia!$C$1:$Z$1,0)+COLUMNS(referencia!$C:O)-1)))," ") -> 7 | P40: =IFERROR((INDEX(referencia!$C8:$Z8,1,(MATCH(referencia!$A8,referencia!$C$1:$Z$1,0)+COLUMNS(referencia!$C:P)-1)))," ") -> 6 | Q40: =IFERROR((INDEX(referencia!$C8:$Z8,1,(MATCH(referencia!$A8,referencia!$C$1:$Z$1,0)+COLUMNS(referencia!$C:Q)-1)))," ") -> 6 | R40: =IFERROR((INDEX(referencia!$C8:$Z8,1,(MATCH(referencia!$A8,referencia!$C$1:$Z$1,0)+COLUMNS(referencia!$C:R)-1)))," ") -> 6 | S40: =IFERROR((INDEX(referencia!$C8:$Z8,1,(MATCH(referencia!$A8,referencia!$C$1:$Z$1,0)+COLUMNS(referencia!$C:S)-1)))," ") -> 5 | T40: =IFERROR((INDEX(referencia!$C8:$Z8,1,(MATCH(referencia!$A8,referencia!$C$1:$Z$1,0)+COLUMNS(referencia!$C:T)-1)))," ") -> 5 | U40: =IFERROR((INDEX(referencia!$C8:$Z8,1,(MATCH(referencia!$A8,referencia!$C$1:$Z$1,0)+COLUMNS(referencia!$C:U)-1)))," ") | V40: =IFERROR((INDEX(referencia!$C8:$Z8,1,(MATCH(referencia!$A8,referencia!$C$1:$Z$1,0)+COLUMNS(referencia!$C:V)-1)))," ") | W40: =IFERROR((INDEX(referencia!$C8:$Z8,1,(MATCH(referencia!$A8,referencia!$C$1:$Z$1,0)+COLUMNS(referencia!$C:W)-1)))," ") | X40: =IFERROR((INDEX(referencia!$C8:$Z8,1,(MATCH(referencia!$A8,referencia!$C$1:$Z$1,0)+COLUMNS(referencia!$C:X)-1)))," ") | Y40: =IFERROR((INDEX(referencia!$C8:$Z8,1,(MATCH(referencia!$A8,referencia!$C$1:$Z$1,0)+COLUMNS(referencia!$C:Y)-1)))," ") | Z40: =IFERROR((INDEX(referencia!$C8:$Z8,1,(MATCH(referencia!$A8,referencia!$C$1:$Z$1,0)+COLUMNS(referencia!$C:Z)-1)))," ")
A41: 43678 | B41: 4 | C41: =IFERROR((INDEX(referencia!$C9:$Z9,1,(MATCH(referencia!$A9,referencia!$C$1:$Z$1,0)+COLUMNS(referencia!$C:C)-1)))," ") -> 4 | D41: =IFERROR((INDEX(referencia!$C9:$Z9,1,(MATCH(referencia!$A9,referencia!$C$1:$Z$1,0)+COLUMNS(referencia!$C:D)-1)))," ") -> 3 | E41: =IFERROR((INDEX(referencia!$C9:$Z9,1,(MATCH(referencia!$A9,referencia!$C$1:$Z$1,0)+COLUMNS(referencia!$C:E)-1)))," ") -> 3 | F41: =IFERROR((INDEX(referencia!$C9:$Z9,1,(MATCH(referencia!$A9,referencia!$C$1:$Z$1,0)+COLUMNS(referencia!$C:F)-1)))," ") -> 3 | G41: =IFERROR((INDEX(referencia!$C9:$Z9,1,(MATCH(referencia!$A9,referencia!$C$1:$Z$1,0)+COLUMNS(referencia!$C:G)-1)))," ") -> 3 | H41: =IFERROR((INDEX(referencia!$C9:$Z9,1,(MATCH(referencia!$A9,referencia!$C$1:$Z$1,0)+COLUMNS(referencia!$C:H)-1)))," ") -> 3 | I41: =IFERROR((INDEX(referencia!$C9:$Z9,1,(MATCH(referencia!$A9,referencia!$C$1:$Z$1,0)+COLUMNS(referencia!$C:I)-1)))," ") -> 3 | J41: =IFERROR((INDEX(referencia!$C9:$Z9,1,(MATCH(referencia!$A9,referencia!$C$1:$Z$1,0)+COLUMNS(referencia!$C:J)-1)))," ") -> 3 | K41: =IFERROR((INDEX(referencia!$C9:$Z9,1,(MATCH(referencia!$A9,referencia!$C$1:$Z$1,0)+COLUMNS(referencia!$C:K)-1)))," ") -> 3 | L41: =IFERROR((INDEX(referencia!$C9:$Z9,1,(MATCH(referencia!$A9,referencia!$C$1:$Z$1,0)+COLUMNS(referencia!$C:L)-1)))," ") -> 3 | M41: =IFERROR((INDEX(referencia!$C9:$Z9,1,(MATCH(referencia!$A9,referencia!$C$1:$Z$1,0)+COLUMNS(referencia!$C:M)-1)))," ") -> 3 | N41: =IFERROR((INDEX(referencia!$C9:$Z9,1,(MATCH(referencia!$A9,referencia!$C$1:$Z$1,0)+COLUMNS(referencia!$C:N)-1)))," ") -> 3 | O41: =IFERROR((INDEX(referencia!$C9:$Z9,1,(MATCH(referencia!$A9,referencia!$C$1:$Z$1,0)+COLUMNS(referencia!$C:O)-1)))," ") -> 3 | P41: =IFERROR((INDEX(referencia!$C9:$Z9,1,(MATCH(referencia!$A9,referencia!$C$1:$Z$1,0)+COLUMNS(referencia!$C:P)-1)))," ") -> 3 | Q41: =IFERROR((INDEX(referencia!$C9:$Z9,1,(MATCH(referencia!$A9,referencia!$C$1:$Z$1,0)+COLUMNS(referencia!$C:Q)-1)))," ") -> 3 | R41: =IFERROR((INDEX(referencia!$C9:$Z9,1,(MATCH(referencia!$A9,referencia!$C$1:$Z$1,0)+COLUMNS(referencia!$C:R)-1)))," ") -> 3 | S41: =IFERROR((INDEX(referencia!$C9:$Z9,1,(MATCH(referencia!$A9,referencia!$C$1:$Z$1,0)+COLUMNS(referencia!$C:S)-1)))," ") -> 3 | T41: =IFERROR((INDEX(referencia!$C9:$Z9,1,(MATCH(referencia!$A9,referencia!$C$1:$Z$1,0)+COLUMNS(referencia!$C:T)-1)))," ") | U41: =IFERROR((INDEX(referencia!$C9:$Z9,1,(MATCH(referencia!$A9,referencia!$C$1:$Z$1,0)+COLUMNS(referencia!$C:U)-1)))," ") | V41: =IFERROR((INDEX(referencia!$C9:$Z9,1,(MATCH(referencia!$A9,referencia!$C$1:$Z$1,0)+COLUMNS(referencia!$C:V)-1)))," ") | W41: =IFERROR((INDEX(referencia!$C9:$Z9,1,(MATCH(referencia!$A9,referencia!$C$1:$Z$1,0)+COLUMNS(referencia!$C:W)-1)))," ") | X41: =IFERROR((INDEX(referencia!$C9:$Z9,1,(MATCH(referencia!$A9,referencia!$C$1:$Z$1,0)+COLUMNS(referencia!$C:X)-1)))," ") | Y41: =IFERROR((INDEX(referencia!$C9:$Z9,1,(MATCH(referencia!$A9,referencia!$C$1:$Z$1,0)+COLUMNS(referencia!$C:Y)-1)))," ") | Z41: =IFERROR((INDEX(referencia!$C9:$Z9,1,(MATCH(referencia!$A9,referencia!$C$1:$Z$1,0)+COLUMNS(referencia!$C:Z)-1)))," ")
A42: 43709 | B42: 8 | C42: =IFERROR((INDEX(referencia!$C10:$Z10,1,(MATCH(referencia!$A10,referencia!$C$1:$Z$1,0)+COLUMNS(referencia!$C:C)-1)))," ") -> 8 | D42: =IFERROR((INDEX(referencia!$C10:$Z10,1,(MATCH(referencia!$A10,referencia!$C$1:$Z$1,0)+COLUMNS(referencia!$C:D)-1)))," ") -> 8 | E42: =IFERROR((INDEX(referencia!$C10:$Z10,1,(MATCH(referencia!$A10,referencia!$C$1:$Z$1,0)+COLUMNS(referencia!$C:E)-1)))," ") -> 7 | F42: =IFERROR((INDEX(referencia!$C10:$Z10,1,(MATCH(referencia!$A10,referencia!$C$1:$Z$1,0)+COLUMNS(referencia!$C:F)-1)))," ") -> 7 | G42: =IFERROR((INDEX(referencia!$C10:$Z10,1,(MATCH(referencia!$A10,referencia!$C$1:$Z$1,0)+COLUMNS(referencia!$C:G)-1)))," ") -> 6 | H42: =IFERROR((INDEX(referencia!$C10:$Z10,1,(MATCH(referencia!$A10,referencia!$C$1:$Z$1,0)+COLUMNS(referencia!$C:H)-1)))," ") -> 6 | I42: =IFERROR((INDEX(referencia!$C10:$Z10,1,(MATCH(referencia!$A10,referencia!$C$1:$Z$1,0)+COLUMNS(referencia!$C:I)-1)))," ") -> 6 | J42: =IFERROR((INDEX(referencia!$C10:$Z10,1,(MATCH(referencia!$A10,referencia!$C$1:$Z$1,0)+COLUMNS(referencia!$C:J)-1)))," ") -> 6 | K42: =IFERROR((INDEX(referencia!$C10:$Z10,1,(MATCH(referencia!$A10,referencia!$C$1:$Z$1,0)+COLUMNS(referencia!$C:K)-1)))," ") -> 6 | L42: =IFERROR((INDEX(referencia!$C10:$Z10,1,(MATCH(referencia!$A10,referencia!$C$1:$Z$1,0)+COLUMNS(referencia!$C:L)-1)))," ") -> 6 | M42: =IFERROR((INDEX(referencia!$C10:$Z10,1,(MATCH(referencia!$A10,referencia!$C$1:$Z$1,0)+COLUMNS(referencia!$C:M)-1)))," ") -> 6 | N42: =IFERROR((INDEX(referencia!$C10:$Z10,1,(MATCH(referencia!$A10,referencia!$C$1:$Z$1,0)+COLUMNS(referencia!$C:N)-1)))," ") -> 6 | O42: =IFERROR((INDEX(referencia!$C10:$Z10,1,(MATCH(referencia!$A10,referencia!$C$1:$Z$1,0)+COLUMNS(referencia!$C:O)-1)))," ") -> 4 | P42: =IFERROR((INDEX(referencia!$C10:$Z10,1,(MATCH(referencia!$A10,referencia!$C$1:$Z$1,0)+COLUMNS(referencia!$C:P)-1)))," ") -> 4 | Q42: =IFERROR((INDEX(referencia!$C10:$Z10,1,(MATCH(referencia!$A10,referencia!$C$1:$Z$1,0)+COLUMNS(referencia!$C:Q)-1)))," ") -> 4 | R42: =IFERROR((INDEX(referencia!$C10:$Z10,1,(MATCH(referencia!$A10,referencia!$C$1:$Z$1,0)+COLUMNS(referencia!$C:R)-1)))," ") -> 4 | S42: =IFERROR((INDEX(referencia!$C10:$Z10,1,(MATCH(referencia!$A10,referencia!$C$1:$Z$1,0)+COLUMNS(referencia!$C:S)-1)))," ") | T42: =IFERROR((INDEX(referencia!$C10:$Z10,1,(MATCH(referencia!$A10,referencia!$C$1:$Z$1,0)+COLUMNS(referencia!$C:T)-1)))," ") | U42: =IFERROR((INDEX(referencia!$C10:$Z10,1,(MATCH(referencia!$A10,referencia!$C$1:$Z$1,0)+COLUMNS(referencia!$C:U)-1)))," ") | V42: =IFERROR((INDEX(referencia!$C10:$Z10,1,(MATCH(referencia!$A10,referencia!$C$1:$Z$1,0)+COLUMNS(referencia!$C:V)-1)))," ") | W42: =IFERROR((INDEX(referencia!$C10:$Z10,1,(MATCH(referencia!$A10,referencia!$C$1:$Z$1,0)+COLUMNS(referencia!$C:W)-1)))," ") | X42: =IFERROR((INDEX(referencia!$C10:$Z10,1,(MATCH(referencia!$A10,referencia!$C$1:$Z$1,0)+COLUMNS(referencia!$C:X)-1)))," ") | Y42: =IFERROR((INDEX(referencia!$C10:$Z10,1,(MATCH(referencia!$A10,referencia!$C$1:$Z$1,0)+COLUMNS(referencia!$C:Y)-1)))," ") | Z42: =IFERROR((INDEX(referencia!$C10:$Z10,1,(MATCH(referencia!$A10,referencia!$C$1:$Z$1,0)+COLUMNS(referencia!$C:Z)-1)))," ")
A43: 43739 | B43: 15 | C43: =IFERROR((INDEX(referencia!$C11:$Z11,1,(MATCH(referencia!$A11,referencia!$C$1:$Z$1,0)+COLUMNS(referencia!$C:C)-1)))," ") -> 15 | D43: =IFERROR((INDEX(referencia!$C11:$Z11,1,(MATCH(referencia!$A11,referencia!$C$1:$Z$1,0)+COLUMNS(referencia!$C:D)-1)))," ") -> 15 | E43: =IFERROR((INDEX(referencia!$C11:$Z11,1,(MATCH(referencia!$A11,referencia!$C$1:$Z$1,0)+COLUMNS(referencia!$C:E)-1)))," ") -> 15 | F43: =IFERROR((INDEX(referencia!$C11:$Z11,1,(MATCH(referencia!$A11,referencia!$C$1:$Z$1,0)+COLUMNS(referencia!$C:F)-1)))," ") -> 15 | G43: =IFERROR((INDEX(referencia!$C11:$Z11,1,(MATCH(referencia!$A11,referencia!$C$1:$Z$1,0)+COLUMNS(referencia!$C:G)-1)))," ") -> 15 | H43: =IFERROR((INDEX(referencia!$C11:$Z11,1,(MATCH(referencia!$A11,referencia!$C$1:$Z$1,0)+COLUMNS(referencia!$C:H)-1)))," ") -> 14 | I43: =IFERROR((INDEX(referencia!$C11:$Z11,1,(MATCH(referencia!$A11,referencia!$C$1:$Z$1,0)+COLUMNS(referencia!$C:I)-1)))," ") -> 14 | J43: =IFERROR((INDEX(referencia!$C11:$Z11,1,(MATCH(referencia!$A11,referencia!$C$1:$Z$1,0)+COLUMNS(referencia!$C:J)-1)))," ") -> 14 | K43: =IFERROR((INDEX(referencia!$C11:$Z11,1,(MATCH(referencia!$A11,referencia!$C$1:$Z$1,0)+COLUMNS(referencia!$C:K)-1)))," ") -> 14 | L43: =IFERROR((INDEX(referencia!$C11:$Z11,1,(MATCH(referencia!$A11,referencia!$C$1:$Z$1,0)+COLUMNS(referencia!$C:L)-1)))," ") -> 13 | M43: =IFERROR((INDEX(referencia!$C11:$Z11,1,(MATCH(referencia!$A11,referencia!$C$1:$Z$1,0)+COLUMNS(referencia!$C:M)-1)))," ") -> 13 | N43: =IFERROR((INDEX(referencia!$C11:$Z11,1,(MATCH(referencia!$A11,referencia!$C$1:$Z$1,0)+COLUMNS(referencia!$C:N)-1)))," ") -> 13 | O43: =IFERROR((INDEX(referencia!$C11:$Z11,1,(MATCH(referencia!$A11,referencia!$C$1:$Z$1,0)+COLUMNS(referencia!$C:O)-1)))," ") -> 12 | P43: =IFERROR((INDEX(referencia!$C11:$Z11,1,(MATCH(referencia!$A11,referencia!$C$1:$Z$1,0)+COLUMNS(referencia!$C:P)-1)))," ") -> 11 | Q43: =IFERROR((INDEX(referencia!$C11:$Z11,1,(MATCH(referencia!$A11,referencia!$C$1:$Z$1,0)+COLUMNS(referencia!$C:Q)-1)))," ") -> 11 | R43: =IFERROR((INDEX(referencia!$C11:$Z11,1,(MATCH(referencia!$A11,referencia!$C$1:$Z$1,0)+COLUMNS(referencia!$C:R)-1)))," ") | S43: =IFERROR((INDEX(referencia!$C11:$Z11,1,(MATCH(referencia!$A11,referencia!$C$1:$Z$1,0)+COLUMNS(referencia!$C:S)-1)))," ") | T43: =IFERROR((INDEX(referencia!$C11:$Z11,1,(MATCH(referencia!$A11,referencia!$C$1:$Z$1,0)+COLUMNS(referencia!$C:T)-1)))," ") | U43: =IFERROR((INDEX(referencia!$C11:$Z11,1,(MATCH(referencia!$A11,referencia!$C$1:$Z$1,0)+COLUMNS(referencia!$C:U)-1)))," ") | V43: =IFERROR((INDEX(referencia!$C11:$Z11,1,(MATCH(referencia!$A11,referencia!$C$1:$Z$1,0)+COLUMNS(referencia!$C:V)-1)))," ") | W43: =IFERROR((INDEX(referencia!$C11:$Z11,1,(MATCH(referencia!$A11,referencia!$C$1:$Z$1,0)+COLUMNS(referencia!$C:W)-1)))," ") | X43: =IFERROR((INDEX(referencia!$C11:$Z11,1,(MATCH(referencia!$A11,referencia!$C$1:$Z$1,0)+COLUMNS(referencia!$C:X)-1)))," ") | Y43: =IFERROR((INDEX(referencia!$C11:$Z11,1,(MATCH(referencia!$A11,referencia!$C$1:$Z$1,0)+COLUMNS(referencia!$C:Y)-1)))," ") | Z43: =IFERROR((INDEX(referencia!$C11:$Z11,1,(MATCH(referencia!$A11,referencia!$C$1:$Z$1,0)+COLUMNS(referencia!$C:Z)-1)))," ")
A44: 43770 | B44: 13 | C44: =IFERROR((INDEX(referencia!$C12:$Z12,1,(MATCH(referencia!$A12,referencia!$C$1:$Z$1,0)+COLUMNS(referencia!$C:C)-1)))," ") -> 13 | D44: =IFERROR((INDEX(referencia!$C12:$Z12,1,(MATCH(referencia!$A12,referencia!$C$1:$Z$1,0)+COLUMNS(referencia!$C:D)-1)))," ") -> 13 | E44: =IFERROR((INDEX(referencia!$C12:$Z12,1,(MATCH(referencia!$A12,referencia!$C$1:$Z$1,0)+COLUMNS(referencia!$C:E)-1)))," ") -> 13 | F44: =IFERROR((INDEX(referencia!$C12:$Z12,1,(MATCH(referencia!$A12,referencia!$C$1:$Z$1,0)+COLUMNS(referencia!$C:F)-1)))," ") -> 13 | G44: =IFERROR((INDEX(referencia!$C12:$Z12,1,(MATCH(referencia!$A12,referencia!$C$1:$Z$1,0)+COLUMNS(referencia!$C:G)-1)))," ") -> 13 | H44: =IFERROR((INDEX(referencia!$C12:$Z12,1,(MATCH(referencia!$A12,referencia!$C$1:$Z$1,0)+COLUMNS(referencia!$C:H)-1)))," ") -> 12 | I44: =IFERROR((INDEX(referencia!$C12:$Z12,1,(MATCH(referencia!$A12,referencia!$C$1:$Z$1,0)+COLUMNS(referencia!$C:I)-1)))," ") -> 10 | J44: =IFERROR((INDEX(referencia!$C12:$Z12,1,(MATCH(referencia!$A12,referencia!$C$1:$Z$1,0)+COLUMNS(referencia!$C:J)-1)))," ") -> 10 | K44: =IFERROR((INDEX(referencia!$C12:$Z12,1,(MATCH(referencia!$A12,referencia!$C$1:$Z$1,0)+COLUMNS(referencia!$C:K)-1)))," ") -> 10 | L44: =IFERROR((INDEX(referencia!$C12:$Z12,1,(MATCH(referencia!$A12,referencia!$C$1:$Z$1,0)+COLUMNS(referencia!$C:L)-1)))," ") -> 10 | M44: =IFERROR((INDEX(referencia!$C12:$Z12,1,(MATCH(referencia!$A12,referencia!$C$1:$Z$1,0)+COLUMNS(referencia!$C:M)-1)))," ") -> 10 | N44: =IFERROR((INDEX(referencia!$C12:$Z12,1,(MATCH(referencia!$A12,referencia!$C$1:$Z$1,0)+COLUMNS(referencia!$C:N)-1)))," ") -> 10 | O44: =IFERROR((INDEX(referencia!$C12:$Z12,1,(MATCH(referencia!$A12,referencia!$C$1:$Z$1,0)+COLUMNS(referencia!$C:O)-1)))," ") -> 10 | P44: =IFERROR((INDEX(referencia!$C12:$Z12,1,(MATCH(referencia!$A12,referencia!$C$1:$Z$1,0)+COLUMNS(referencia!$C:P)-1)))," ") -> 9 | Q44: =IFERROR((INDEX(referencia!$C12:$Z12,1,(MATCH(referencia!$A12,referencia!$C$1:$Z$1,0)+COLUMNS(referencia!$C:Q)-1)))," ") | R44: =IFERROR((INDEX(referencia!$C12:$Z12,1,(MATCH(referencia!$A12,referencia!$C$1:$Z$1,0)+COLUMNS(referencia!$C:R)-1)))," ") | S44: =IFERROR((INDEX(referencia!$C12:$Z12,1,(MATCH(referencia!$A12,referencia!$C$1:$Z$1,0)+COLUMNS(referencia!$C:S)-1)))," ") | T44: =IFERROR((INDEX(referencia!$C12:$Z12,1,(MATCH(referencia!$A12,referencia!$C$1:$Z$1,0)+COLUMNS(referencia!$C:T)-1)))," ") | U44: =IFERROR((INDEX(referencia!$C12:$Z12,1,(MATCH(referencia!$A12,referencia!$C$1:$Z$1,0)+COLUMNS(referencia!$C:U)-1)))," ") | V44: =IFERROR((INDEX(referencia!$C12:$Z12,1,(MATCH(referencia!$A12,referencia!$C$1:$Z$1,0)+COLUMNS(referencia!$C:V)-1)))," ") | W44: =IFERROR((INDEX(referencia!$C12:$Z12,1,(MATCH(referencia!$A12,referencia!$C$1:$Z$1,0)+COLUMNS(referencia!$C:W)-1)))," ") | X44: =IFERROR((INDEX(referencia!$C12:$Z12,1,(MATCH(referencia!$A12,referencia!$C$1:$Z$1,0)+COLUMNS(referencia!$C:X)-1)))," ") | Y44: =IFERROR((INDEX(referencia!$C12:$Z12,1,(MATCH(referencia!$A12,referencia!$C$1:$Z$1,0)+COLUMNS(referencia!$C:Y)-1)))," ") | Z44: =IFERROR((INDEX(referencia!$C12:$Z12,1,(MATCH(referencia!$A12,referencia!$C$1:$Z$1,0)+COLUMNS(referencia!$C:Z)-1)))," ")
A45: 43800 | B45: 6 | C45: =IFERROR((INDEX(referencia!$C13:$Z13,1,(MATCH(referencia!$A13,referencia!$C$1:$Z$1,0)+COLUMNS(referencia!$C:C)-1)))," ") -> 6 | D45: =IFERROR((INDEX(referencia!$C13:$Z13,1,(MATCH(referencia!$A13,referencia!$C$1:$Z$1,0)+COLUMNS(referencia!$C:D)-1)))," ") -> 6 | E45: =IFERROR((INDEX(referencia!$C13:$Z13,1,(MATCH(referencia!$A13,referencia!$C$1:$Z$1,0)+COLUMNS(referencia!$C:E)-1)))," ") -> 6 | F45: =IFERROR((INDEX(referencia!$C13:$Z13,1,(MATCH(referencia!$A13,referencia!$C$1:$Z$1,0)+COLUMNS(referencia!$C:F)-1)))," ") -> 6 | G45: =IFERROR((INDEX(referencia!$C13:$Z13,1,(MATCH(referencia!$A13,referencia!$C$1:$Z$1,0)+COLUMNS(referencia!$C:G)-1)))," ") -> 6 | H45: =IFERROR((INDEX(referencia!$C13:$Z13,1,(MATCH(referencia!$A13,referencia!$C$1:$Z$1,0)+COLUMNS(referencia!$C:H)-1)))," ") -> 6 | I45: =IFERROR((INDEX(referencia!$C13:$Z13,1,(MATCH(referencia!$A13,referencia!$C$1:$Z$1,0)+COLUMNS(referencia!$C:I)-1)))," ") -> 6 | J45: =IFERROR((INDEX(referencia!$C13:$Z13,1,(MATCH(referencia!$A13,referencia!$C$1:$Z$1,0)+COLUMNS(referencia!$C:J)-1)))," ") -> 6 | K45: =IFERROR((INDEX(referencia!$C13:$Z13,1,(MATCH(referencia!$A13,referencia!$C$1:$Z$1,0)+COLUMNS(referencia!$C:K)-1)))," ") -> 6 | L45: =IFERROR((INDEX(referencia!$C13:$Z13,1,(MATCH(referencia!$A13,referencia!$C$1:$Z$1,0)+COLUMNS(referencia!$C:L)-1)))," ") -> 6 | M45: =IFERROR((INDEX(referencia!$C13:$Z13,1,(MATCH(referencia!$A13,referencia!$C$1:$Z$1,0)+COLUMNS(referencia!$C:M)-1)))," ") -> 6 | N45: =IFERROR((INDEX(referencia!$C13:$Z13,1,(MATCH(referencia!$A13,referencia!$C$1:$Z$1,0)+COLUMNS(referencia!$C:N)-1)))," ") -> 6 | O45: =IFERROR((INDEX(referencia!$C13:$Z13,1,(MATCH(referencia!$A13,referencia!$C$1:$Z$1,0)+COLUMNS(referencia!$C:O)-1)))," ") -> 6 | P45: =IFERROR((INDEX(referencia!$C13:$Z13,1,(MATCH(referencia!$A13,referencia!$C$1:$Z$1,0)+COLUMNS(referencia!$C:P)-1)))," ") | Q45: =IFERROR((INDEX(referencia!$C13:$Z13,1,(MATCH(referencia!$A13,referencia!$C$1:$Z$1,0)+COLUMNS(referencia!$C:Q)-1)))," ") | R45: =IFERROR((INDEX(referencia!$C13:$Z13,1,(MATCH(referencia!$A13,referencia!$C$1:$Z$1,0)+COLUMNS(referencia!$C:R)-1)))," ") | S45: =IFERROR((INDEX(referencia!$C13:$Z13,1,(MATCH(referencia!$A13,referencia!$C$1:$Z$1,0)+COLUMNS(referencia!$C:S)-1)))," ") | T45: =IFERROR((INDEX(referencia!$C13:$Z13,1,(MATCH(referencia!$A13,referencia!$C$1:$Z$1,0)+COLUMNS(referencia!$C:T)-1)))," ") | U45: =IFERROR((INDEX(referencia!$C13:$Z13,1,(MATCH(referencia!$A13,referencia!$C$1:$Z$1,0)+COLUMNS(referencia!$C:U)-1)))," ") | V45: =IFERROR((INDEX(referencia!$C13:$Z13,1,(MATCH(referencia!$A13,referencia!$C$1:$Z$1,0)+COLUMNS(referencia!$C:V)-1)))," ") | W45: =IFERROR((INDEX(referencia!$C13:$Z13,1,(MATCH(referencia!$A13,referencia!$C$1:$Z$1,0)+COLUMNS(referencia!$C:W)-1)))," ") | X45: =IFERROR((INDEX(referencia!$C13:$Z13,1,(MATCH(referencia!$A13,referencia!$C$1:$Z$1,0)+COLUMNS(referencia!$C:X)-1)))," ") | Y45: =IFERROR((INDEX(referencia!$C13:$Z13,1,(MATCH(referencia!$A13,referencia!$C$1:$Z$1,0)+COLUMNS(referencia!$C:Y)-1)))," ") | Z45: =IFERROR((INDEX(referencia!$C13:$Z13,1,(MATCH(referencia!$A13,referencia!$C$1:$Z$1,0)+COLUMNS(referencia!$C:Z)-1)))," ")
... A57: 44166 | B57: 16 | C57: =IFERROR((INDEX(referencia!$C25:$Z25,1,(MATCH(referencia!$A25,referencia!$C$1:$Z$1,0)+COLUMNS(referencia!$C:C)-1)))," ") -> 16 | D57: =IFERROR((INDEX(referencia!$C25:$Z25,1,(MATCH(referencia!$A25,referencia!$C$1:$Z$1,0)+COLUMNS(referencia!$C:D)-1)))," ") | E57: =IFERROR((INDEX(referencia!$C25:$Z25,1,(MATCH(referencia!$A25,referencia!$C$1:$Z$1,0)+COLUMNS(referencia!$C:E)-1)))," ") | F57: =IFERROR((INDEX(referencia!$C25:$Z25,1,(MATCH(referencia!$A25,referencia!$C$1:$Z$1,0)+COLUMNS(referencia!$C:F)-1)))," ") | G57: =IFERROR((INDEX(referencia!$C25:$Z25,1,(MATCH(referencia!$A25,referencia!$C$1:$Z$1,0)+COLUMNS(referencia!$C:G)-1)))," ") | H57: =IFERROR((INDEX(referencia!$C25:$Z25,1,(MATCH(referencia!$A25,referencia!$C$1:$Z$1,0)+COLUMNS(referencia!$C:H)-1)))," ") | I57: =IFERROR((INDEX(referencia!$C25:$Z25,1,(MATCH(referencia!$A25,referencia!$C$1:$Z$1,0)+COLUMNS(referencia!$C:I)-1)))," ") | J57: =IFERROR((INDEX(referencia!$C25:$Z25,1,(MATCH(referencia!$A25,referencia!$C$1:$Z$1,0)+COLUMNS(referencia!$C:J)-1)))," ") | K57: =IFERROR((INDEX(referencia!$C25:$Z25,1,(MATCH(referencia!$A25,referencia!$C$1:$Z$1,0)+COLUMNS(referencia!$C:K)-1)))," ") | L57: =IFERROR((INDEX(referencia!$C25:$Z25,1,(MATCH(referencia!$A25,referencia!$C$1:$Z$1,0)+COLUMNS(referencia!$C:L)-1)))," ") | M57: =IFERROR((INDEX(referencia!$C25:$Z25,1,(MATCH(referencia!$A25,referencia!$C$1:$Z$1,0)+COLUMNS(referencia!$C:M)-1)))," ") | N57: =IFERROR((INDEX(referencia!$C25:$Z25,1,(MATCH(referencia!$A25,referencia!$C$1:$Z$1,0)+COLUMNS(referencia!$C:N)-1)))," ") | O57: =IFERROR((INDEX(referencia!$C25:$Z25,1,(MATCH(referencia!$A25,referencia!$C$1:$Z$1,0)+COLUMNS(referencia!$C:O)-1)))," ") | P57: =IFERROR((INDEX(referencia!$C25:$Z25,1,(MATCH(referencia!$A25,referencia!$C$1:$Z$1,0)+COLUMNS(referencia!$C:P)-1)))," ") | Q57: =IFERROR((INDEX(referencia!$C25:$Z25,1,(MATCH(referencia!$A25,referencia!$C$1:$Z$1,0)+COLUMNS(referencia!$C:Q)-1)))," ") | R57: =IFERROR((INDEX(referencia!$C25:$Z25,1,(MATCH(referencia!$A25,referencia!$C$1:$Z$1,0)+COLUMNS(referencia!$C:R)-1)))," ") | S57: =IFERROR((INDEX(referencia!$C25:$Z25,1,(MATCH(referencia!$A25,referencia!$C$1:$Z$1,0)+COLUMNS(referencia!$C:S)-1)))," ") | T57: =IFERROR((INDEX(referencia!$C25:$Z25,1,(MATCH(referencia!$A25,referencia!$C$1:$Z$1,0)+COLUMNS(referencia!$C:T)-1)))," ") | U57: =IFERROR((INDEX(referencia!$C25:$Z25,1,(MATCH(referencia!$A25,referencia!$C$1:$Z$1,0)+COLUMNS(referencia!$C:U)-1)))," ") | V57: =IFERROR((INDEX(referencia!$C25:$Z25,1,(MATCH(referencia!$A25,referencia!$C$1:$Z$1,0)+COLUMNS(referencia!$C:V)-1)))," ") | W57: =IFERROR((INDEX(referencia!$C25:$Z25,1,(MATCH(referencia!$A25,referencia!$C$1:$Z$1,0)+COLUMNS(referencia!$C:W)-1)))," ") | X57: =IFERROR((INDEX(referencia!$C25:$Z25,1,(MATCH(referencia!$A25,referencia!$C$1:$Z$1,0)+COLUMNS(referencia!$C:X)-1)))," ") | Y57: =IFERROR((INDEX(referencia!$C25:$Z25,1,(MATCH(referencia!$A25,referencia!$C$1:$Z$1,0)+COLUMNS(referencia!$C:Y)-1)))," ") | Z57: =IFERROR((INDEX(referencia!$C25:$Z25,1,(MATCH(referencia!$A25,referencia!$C$1:$Z$1,0)+COLUMNS(referencia!$C:Z)-1)))," ")
A58: Total | C58: =SUM(C34:C57) -> 330 | D58: =SUM(D34:D57) -> 311 | E58: =SUM(E34:E57) -> 295 | F58: =SUM(F34:F57) -> 272 | G58: =SUM(G34:G57) -> 254 | H58: =SUM(H34:H57) -> 220 | I58: =SUM(I34:I57) -> 192 | J58: =SUM(J34:J57) -> 171 | ... Z58: =SUM(Z34:Z57) -> 7
A65: Mes de Registro | B65: Nuevos Clientes | C65: mes 1 | D65: mes 2 | E65: mes 3 | F65: mes 4 | G65: mes 5 | H65: mes 6 | I65: mes 7 | J65: mes 8 | K65: mes 9 | L65: mes 10 | M65: mes 11 | N65: mes 12 | O65: mes 13 | P65: mes 14 | Q65: mes 15 | R65: mes 16 | S65: mes 17 | T65: mes 18 | U65: mes 19 | V65: mes 20 | W65: mes 21 | X65: mes 22 | Y65: mes 23 | Z65: mes 24
